Workbook

Sheet 견적서
A2: 見 積 書
A4: 관리No. : | D4: 견적일자 : | E4: =TODAY() -> 42705
A5: 수 신 : 貴中
A6: 참 조 :
A8: 下記와 如히 見積합니다.
A10: ="合計金額 (공급가 + V.A.T) : 일금 "&NUMBERSTRING(F48*1.1,1)&"원정 ("&DOLLAR(F48*1.1)&"--)" -> 合計金額 (공급가 + V.A.T) : 일금 이억일천삼백칠십삼만원정 (₩213,730,000--)
F11: (금액단위: 원, V.A.T.별도)
A12: 예상일정 | B12: 개발기간 | D12: 6개월 | E12: 8개월
B13: Test | D13: 1개월
B14: Go-Live | D14: 1개월
B15: 특이사항 | D15: 1. 본 기간은 현장 상황에 따라서 달라질 수 있습니다. 2. 검수완료 후 무상유지보수 1년 포함입니다.
B16: 업무구분 | D16: 세부 업무 | E16: 단위 | F16: 공 급 가
F17: 단 가 | G17: 금 액
A18: S/W 개발 | B18: WMS 구축 | D18: 입고관리 | E18: 1 | F18: =F29 -> 299011956 | G18: =E18*F18 -> 299011956
D19: 출고관리
D20: 재고관리
D21: PDA
D22: 인터페이스
A24: 등급 | D24: 인건비 근거 | E24: 투입공수 | F24: 단가 | G24: 금액
A25: 개발원가 (한국SW산업협회고시단가) | C25: 특급 | D25: - SW기술자 공인노임단가 : 월 노임단가 19,770,541 | E25: =SUMIFS(공수!$J:$J,공수!$D:$D,$C25) -> 5 | F25: 19770541 | G25: =F25*LEFT(E25,4) -> 98852705
C26: 고급 | D26: - SW기술자 공인노임단가 : 월 노임단가 14,614,387 | E26: =SUMIFS(공수!$J:$J,공수!$D:$D,$C26) -> 0 | F26: 14614387 | G26: =F26*LEFT(E26,4) -> 0
C27: 중급 | D27: - SW기술자 공인노임단가 : 월 노임단가 11,715,166 | E27: =SUMIFS(공수!$J:$J,공수!$D:$D,$C27) -> 14.5 | F27: 11715166 | G27: =F27*LEFT(E27,4) -> 169869907
C28: 초급 | D28: - SW기술자 공인노임단가 : 월 노임단가 10,096,448 | E28: =SUMIFS(공수!$J:$J,공수!$D:$D,$C28) -> 3 | F28: 10096448 | G28: =F28*LEFT(E28,4) -> 30289344
A29: S/W 소 계 | E29: =SUM(E25:E28) -> 22.5 | F29: =SUM(G25:G28) -> 299011956
A30: ① | B30: D/C(35%) 후 소 계(만원이하절사) | E30: =ROUNDDOWN(F29*(100%-(MID(B30,5,3))),-5) -> 194300000
B31: 품명 | D31: 규격 | E31: 단위(EA) | F31: 단가 | G31: 공급가
A32: S/W 패키지
A34: H/W | G34: =E34*F34 -> 0
G36: =E36*F36 -> 0
G38: =E38*F38 -> 0
G40: =E40*F40 -> 0
G42: =E42*F42 -> 0
A43: ② | B43: H/W 소 계(십만원이하절사) | E43: =ROUNDDOWN(SUM(G34:G42),-4) -> 0
A44: 설치 및 지원 | B44: 시스템 설치 | G44: =E44*F44 -> 0
B45: 시스템 교육 | G45: =E45*F45 -> 0
B46: 소모품 | G46: =E46*F46 -> 0
A47: ③ | B47: 설치비(공사비포함) 소 계(십만원이하절사) | E47: =ROUNDDOWN(SUM(G44:G46),-4) -> 0
A48: 합 계 (Total Amount) ( ① + ② + ③ ) | F48: =SUM(E30,E43,E47) -> 194300000
A50: 〈 유의사항 〉
A51: 1. 견적 유효기간 : 견적일로부터 2주
...

Sheet 공수
A1: 역할 | B1: 업무 | D1: 등급 | E1: 분석/설계 | G1: 개발/테스트 | J1: 계 | K1: 참여율 | L1: 단가 | M1: 금액 | S1: 원가 | T1: 이익율 | U1: 이익율 | V1: 이익율 | W1: 이익율 | X1: 이익율
E2: M1 | F2: M2 | G2: M3 | H2: M4 | I2: M5 | N2: 0.2 | O2: 0.3 | P2: 0.35 | Q2: 0.4 | R2: 0.45 | S2: 금액 | T2: DC20% | U2: DC30% | V2: DC35% | W2: DC40% | X2: DC45%
A3: PM | B3: 사업총괄/분석 | D3: 특급 | E3: 1 | F3: 1 | G3: 1 | H3: 1 | I3: 1 | J3: =SUM(E3:I3) -> 5 | K3: =J3/11*100 -> 45.454545 | L3: =VLOOKUP(D3,단가!$A$8:$G$12,7,0) -> 19770000 | M3: =J3*L3 -> 98850000 | N3: =$M3*(100%-N$2) -> 79080000 | O3: =$M3*(100%-O$2) -> 69195000 | P3: =$M3*(100%-P$2) -> 64252500 | Q3: =$M3*(100%-Q$2) -> 59310000 | R3: =$M3*(100%-R$2) -> 54367500 | S3: =J3*VLOOKUP(D3,단가!$A$8:$H$12,8,0) -> 40000000 | T3: =(N3-$S3)/$S3*100 -> 97.7 | U3: =(O3-$S3)/$S3*100 -> 72.9875 | V3: =(P3-$S3)/$S3*100 -> 60.63125 | W3: =(Q3-$S3)/$S3*100 -> 48.275 | X3: =(R3-$S3)/$S3*100 -> 35.91875
A4: Design | B4: 웹/PDA/퍼블리싱/디자인 | D4: 중급 | J4: =SUM(E4:I4) -> 0 | K4: =J4/11*100 -> 0 | L4: =VLOOKUP(D4,단가!$A$8:$G$12,7,0) -> 11715000 | M4: =J4*L4 -> 0 | N4: =$M4*(100%-N$2) -> 0 | O4: =$M4*(100%-O$2) -> 0 | P4: =$M4*(100%-P$2) -> 0 | Q4: =$M4*(100%-Q$2) -> 0 | R4: =$M4*(100%-R$2) -> 0 | S4: =J4*VLOOKUP(D4,단가!$A$8:$H$12,8,0) -> 0 | T4: =(N4-$S4)/$S4*100 -> #DIV/0! | U4: =(O4-$S4)/$S4*100 -> #DIV/0! | V4: =(P4-$S4)/$S4*100 -> #DIV/0! | W4: =(Q4-$S4)/$S4*100 -> #DIV/0! | X4: =(R4-$S4)/$S4*100 -> #DIV/0!
A5: 소계 | E5: =SUM(E3:E4) -> 1 | F5: =SUM(F3:F4) -> 1 | G5: =SUM(G3:G4) -> 1 | H5: =SUM(H3:H4) -> 1 | I5: =SUM(I3:I4) -> 1 | J5: =SUM(J3:J4) -> 5 | M5: =SUM(M3:M4) -> 98850000 | N5: =SUM(N3:N4) -> 79080000 | O5: =SUM(O3:O4) -> 69195000 | P5: =SUM(P3:P4) -> 64252500 | Q5: =SUM(Q3:Q4) -> 59310000 | R5: =SUM(R3:R4) -> 54367500 | S5: =SUM(S3:S4) -> 40000000 | T5: =(N5-$S5)/$S5*100 -> 97.7 | U5: =(O5-$S5)/$S5*100 -> 72.9875 | V5: =(P5-$S5)/$S5*100 -> 60.63125 | W5: =(Q5-$S5)/$S5*100 -> 48.275 | X5: =(R5-$S5)/$S5*100 -> 35.91875
A6: PL | B6: 설계 | D6: 중급 | E6: 1 | F6: 1 | G6: 1 | H6: 1 | I6: 1 | J6: =SUM(E6:I6) -> 5 | K6: =J6/11*100 -> 45.454545 | L6: =VLOOKUP(D6,단가!$A$8:$G$12,7,0) -> 11715000 | M6: =J6*L6 -> 58575000 | N6: =$M6*(100%-N$2) -> 46860000 | O6: =$M6*(100%-O$2) -> 41002500 | P6: =$M6*(100%-P$2) -> 38073750 | Q6: =$M6*(100%-Q$2) -> 35145000 | R6: =$M6*(100%-R$2) -> 32216250 | S6: =J6*VLOOKUP(D6,단가!$A$8:$H$12,8,0) -> 30000000 | T6: =(N6-$S6)/$S6*100 -> 56.2 | U6: =(O6-$S6)/$S6*100 -> 36.675 | V6: =(P6-$S6)/$S6*100 -> 26.9125 | W6: =(Q6-$S6)/$S6*100 -> 17.15 | X6: =(R6-$S6)/$S6*100 -> 7.3875
D7: 중급 | J7: =SUM(E7:I7) -> 0 | K7: =J7/11*100 -> 0 | L7: =VLOOKUP(D7,단가!$A$8:$G$12,7,0) -> 11715000 | M7: =J7*L7 -> 0 | N7: =$M7*(100%-N$2) -> 0 | O7: =$M7*(100%-O$2) -> 0 | P7: =$M7*(100%-P$2) -> 0 | Q7: =$M7*(100%-Q$2) -> 0 | R7: =$M7*(100%-R$2) -> 0 | S7: =J7*VLOOKUP(D7,단가!$A$8:$H$12,8,0) -> 0 | T7: =(N7-$S7)/$S7*100 -> #DIV/0! | U7: =(O7-$S7)/$S7*100 -> #DIV/0! | V7: =(P7-$S7)/$S7*100 -> #DIV/0! | W7: =(Q7-$S7)/$S7*100 -> #DIV/0! | X7: =(R7-$S7)/$S7*100 -> #DIV/0!
A8: 개발 | B8: 인터페이스 | D8: 중급 | F8: 0.5 | G8: 1 | H8: 1 | I8: 1 | J8: =SUM(E8:I8) -> 3.5 | K8: =J8/11*100 -> 31.818182 | L8: =VLOOKUP(D8,단가!$A$8:$G$12,7,0) -> 11715000 | M8: =J8*L8 -> 41002500 | N8: =$M8*(100%-N$2) -> 32802000 | O8: =$M8*(100%-O$2) -> 28701750 | P8: =$M8*(100%-P$2) -> 26651625 | Q8: =$M8*(100%-Q$2) -> 24601500 | R8: =$M8*(100%-R$2) -> 22551375 | S8: =J8*VLOOKUP(D8,단가!$A$8:$H$12,8,0) -> 21000000 | T8: =(N8-$S8)/$S8*100 -> 56.2 | U8: =(O8-$S8)/$S8*100 -> 36.675 | V8: =(P8-$S8)/$S8*100 -> 26.9125 | W8: =(Q8-$S8)/$S8*100 -> 17.15 | X8: =(R8-$S8)/$S8*100 -> 7.3875
A9: 개발 | B9: 마스터,출고,반출 | D9: 초급 | G9: 1 | H9: 1 | I9: 1 | J9: =SUM(E9:I9) -> 3 | K9: =J9/11*100 -> 27.272727 | L9: =VLOOKUP(D9,단가!$A$8:$G$12,7,0) -> 10096000 | M9: =J9*L9 -> 30288000 | N9: =$M9*(100%-N$2) -> 24230400 | O9: =$M9*(100%-O$2) -> 21201600 | P9: =$M9*(100%-P$2) -> 19687200 | Q9: =$M9*(100%-Q$2) -> 18172800 | R9: =$M9*(100%-R$2) -> 16658400 | S9: =J9*VLOOKUP(D9,단가!$A$8:$H$12,8,0) -> 15000000 | T9: =(N9-$S9)/$S9*100 -> 61.536 | U9: =(O9-$S9)/$S9*100 -> 41.344 | V9: =(P9-$S9)/$S9*100 -> 31.248 | W9: =(Q9-$S9)/$S9*100 -> 21.152 | X9: =(R9-$S9)/$S9*100 -> 11.056
A10: 개발 | B10: 마스터,입고,반입,재고 | D10: 중급 | G10: 1 | H10: 1 | I10: 1 | J10: =SUM(E10:I10) -> 3 | K10: =J10/11*100 -> 27.272727 | L10: =VLOOKUP(D10,단가!$A$8:$G$12,7,0) -> 11715000 | M10: =J10*L10 -> 35145000 | N10: =$M10*(100%-N$2) -> 28116000 | O10: =$M10*(100%-O$2) -> 24601500 | P10: =$M10*(100%-P$2) -> 22844250 | Q10: =$M10*(100%-Q$2) -> 21087000 | R10: =$M10*(100%-R$2) -> 19329750 | S10: =J10*VLOOKUP(D10,단가!$A$8:$H$12,8,0) -> 18000000 | T10: =(N10-$S10)/$S10*100 -> 56.2 | U10: =(O10-$S10)/$S10*100 -> 36.675 | V10: =(P10-$S10)/$S10*100 -> 26.9125 | W10: =(Q10-$S10)/$S10*100 -> 17.15 | X10: =(R10-$S10)/$S10*100 -> 7.3875
A11: 개발 | B11: PDA | D11: 중급 | G11: 1 | H11: 1 | I11: 1 | J11: =SUM(E11:I11) -> 3 | K11: =J11/11*100 -> 27.272727 | L11: =VLOOKUP(D11,단가!$A$8:$G$12,7,0) -> 11715000 | M11: =J11*L11 -> 35145000 | N11: =$M11*(100%-N$2) -> 28116000 | O11: =$M11*(100%-O$2) -> 24601500 | P11: =$M11*(100%-P$2) -> 22844250 | Q11: =$M11*(100%-Q$2) -> 21087000 | R11: =$M11*(100%-R$2) -> 19329750 | S11: =J11*VLOOKUP(D11,단가!$A$8:$H$12,8,0) -> 18000000 | T11: =(N11-$S11)/$S11*100 -> 56.2 | U11: =(O11-$S11)/$S11*100 -> 36.675 | V11: =(P11-$S11)/$S11*100 -> 26.9125 | W11: =(Q11-$S11)/$S11*100 -> 17.15 | X11: =(R11-$S11)/$S11*100 -> 7.3875
A12: 소계 | E12: =SUM(E6:E11) -> 1 | F12: =SUM(F6:F11) -> 1.5 | G12: =SUM(G6:G11) -> 5 | H12: =SUM(H6:H11) -> 5 | I12: =SUM(I6:I11) -> 5 | J12: =SUM(J6:J11) -> 17.5 | M12: =SUM(M6:M11) -> 200155500 | N12: =SUM(N6:N11) -> 160124400 | O12: =SUM(O6:O11) -> 140108850 | P12: =SUM(P6:P11) -> 130101075 | Q12: =SUM(Q6:Q11) -> 120093300 | R12: =SUM(R6:R11) -> 110085525 | S12: =SUM(S6:S11) -> 102000000 | T12: =(N12-$S12)/$S12*100 -> 56.984706 | U12: =(O12-$S12)/$S12*100 -> 37.361618 | V12: =(P12-$S12)/$S12*100 -> 27.550074 | W12: =(Q12-$S12)/$S12*100 -> 17.738529 | X12: =(R12-$S12)/$S12*100 -> 7.9269853
A13: 합계 | E13: =E5+E12 -> 2 | F13: =F5+F12 -> 2.5 | G13: =G5+G12 -> 6 | H13: =H5+H12 -> 6 | I13: =I5+I12 -> 6 | J13: =J5+J12 -> 22.5 | M13: =M5+M12 -> 299005500 | N13: =N5+N12 -> 239204400 | O13: =O5+O12 -> 209303850 | P13: =P5+P12 -> 194353575 | Q13: =Q5+Q12 -> 179403300 | R13: =R5+R12 -> 164453025 | S13: =S5+S12 -> 142000000 | T13: =(N13-$S13)/$S13*100 -> 68.453803 | U13: =(O13-$S13)/$S13*100 -> 47.397077 | V13: =(P13-$S13)/$S13*100 -> 36.868715 | W13: =(Q13-$S13)/$S13*100 -> 26.340352 | X13: =(R13-$S13)/$S13*100 -> 15.811989
O14: =N13-O13 -> 29900550 | P14: =O13-P13 -> 14950275 | Q14: =P13-Q13 -> 14950275 | R14: =Q13-R13 -> 14950275

Sheet 단가
A2: 2015년도 소프트웨어 기술자 평균임금
A4: 1. 평균 임금표
G5: (단위 : 원)
A6: 등 급 | B6: 직 접 인 건 비 | E6: ②제경비 | F6: ③기술료 | G6: ④금액 | I6: DC(%)
B7: 단 가 | C7: 일 수 | D7: ①금 액 | E7: 1.1 | F7: 0.2 | G7: ①+②+③ | I7: 10 | J7: 15 | K7: 20 | L7: 25 | M7: 30 | N7: 35 | O7: 40 | P7: 45
A8: 기술사 | B8: 411642 | C8: 21 | D8: =B8*C8 -> 8644482 | E8: =D8*E7 -> 9508930.2 | F8: =(D8+E8)*F7 -> 3630682.4 | G8: =D8+E8+F8 -> 21784095 | H8: 8000000 | I8: =G8*0.9 -> 19605685 | J8: =G8*(100-J7)/100 -> 18516480 | K8: =G8*0.8 -> 17427276 | L8: =$G$8*0.75 -> 16338071 | M8: =$G8*0.7 -> 15248866 | N8: =$G8*0.65 -> 14159662 | O8: =$G8*0.6 -> 13070457 | P8: =$G8*0.55 -> 11981252
A9: 특급 | B9: 373593 | C9: 21 | D9: =B9*C9 -> 7845453 | E9: =D9*E7 -> 8629998.3 | F9: =(D9+E9)*F7 -> 3295090.3 | G9: =TRUNC((D9+E9+F9),-3) -> 19770000 | H9: 8000000 | I9: =G9*0.9 -> 17793000 | J9: =G9*(100-$J$7)/100 -> 16804500 | K9: =G9*0.8 -> 15816000 | L9: =$G$9*0.75 -> 14827500 | M9: =$G9*0.7 -> 13839000 | N9: =$G9*0.65 -> 12850500 | O9: =$G9*0.6 -> 11862000 | P9: =$G9*0.55 -> 10873500
A10: 고급 | B10: 276160 | C10: 21 | D10: =B10*C10 -> 5799360 | E10: =D10*E7 -> 6379296 | F10: =(D10+E10)*F7 -> 2435731.2 | G10: =TRUNC((D10+E10+F10),-3) -> 14614000 | H10: 7000000 | I10: =G10*0.9 -> 13152600 | J10: =G10*(100-$J$7)/100 -> 12421900 | K10: =G10*0.8 -> 11691200 | L10: =$G$10*0.75 -> 10960500 | M10: =$G10*0.7 -> 10229800 | N10: =$G10*0.65 -> 9499100 | O10: =$G10*0.6 -> 8768400 | P10: =$G10*0.55 -> 8037700
A11: 중급 | B11: 221375 | C11: 21 | D11: =B11*C11 -> 4648875 | E11: =D11*E7 -> 5113762.5 | F11: =(D11+E11)*F7 -> 1952527.5 | G11: =TRUNC((D11+E11+F11),-3) -> 11715000 | H11: 6000000 | I11: =G11*0.9 -> 10543500 | J11: =G11*(100-$J$7)/100 -> 9957750 | K11: =G11*0.8 -> 9372000 | L11: =$G$11*0.75 -> 8786250 | M11: =$G11*0.7 -> 8200500 | N11: =$G11*0.65 -> 7614750 | O11: =$G11*0.6 -> 7029000 | P11: =$G11*0.55 -> 6443250
A12: 초급 | B12: 190787 | C12: 21 | D12: =B12*C12 -> 4006527 | E12: =D12*E7 -> 4407179.7 | F12: =(D12+E12)*F7 -> 1682741.3 | G12: =TRUNC((D12+E12+F12),-3) -> 10096000 | H12: 5000000 | I12: =G12*0.9 -> 9086400 | J12: =G12*(100-$J$7)/100 -> 8581600 | K12: =G12*0.8 -> 8076800 | L12: =$G$12*0.75 -> 7572000 | M12: =$G12*0.7 -> 7067200 | N12: =$G12*0.65 -> 6562400 | O12: =$G12*0.6 -> 6057600 | P12: =$G12*0.55 -> 5552800
A14: 2. 비고
A16: 1. 법적근거 : 1) 통계법 제27조(통계의 공표)에 따름 2) 2015년 SW기술자 임금실태조사(통계승인 제37501호) 의 SW기술자 평균임금을 공표. 2. SW기술자 평균임금은 소프트웨어산업진흥법 제22조(소프트웨어사업의 대가지급) 4항 ‘소프트웨어기술자의 노임단가’를 지칭함. 상기 단가는 1일 기준이며, 월 근무일수는 21.0일, 일 근무시간은 8시간으로 산정 함.
H17: 일단가
H18: =(D8+E8+F8)/C8 -> 1037337.8 | I18: =$H$18*0.9 -> 933604.06 | J18: =$H$18*0.85 -> 881737.16 | K18: =$H$18*0.8 -> 829870.27 | L18: =$H$18*0.75 -> 778003.38 | M18: =$H$18*0.7 -> 726136.49 | N18: =$H$18*0.65 -> 674269.6 | O18: =$H$18*0.6 -> 622402.7 | P18: =$H$18*0.55 -> 570535.81
H19: =(D9+E9+F9)/C9 -> 941454.36 | I19: =$H$19*0.9 -> 847308.92 | J19: =$H$19*0.85 -> 800236.21 | K19: =$H$19*0.8 -> 753163.49 | L19: =$H$19*0.75 -> 706090.77 | M19: =$H$19*0.7 -> 659018.05 | N19: =$H$19*0.65 -> 611945.33 | O19: =$H$19*0.6 -> 564872.62 | P19: =$H$19*0.55 -> 517799.9
H20: =(D10+E10+F10)/C10 -> 695923.2 | I20: =$H$20*0.9 -> 626330.88 | J20: =$H$20*0.85 -> 591534.72 | K20: =$H$20*0.8 -> 556738.56 | L20: =$H$20*0.75 -> 521942.4 | M20: =$H$20*0.7 -> 487146.24 | N20: =$H$20*0.65 -> 452350.08 | O20: =$H$20*0.6 -> 417553.92 | P20: =$H$20*0.55 -> 382757.76
H21: =(D11+E11+F11)/C11 -> 557865 | I21: =$H$21*0.9 -> 502078.5 | J21: =$H$21*0.85 -> 474185.25 | K21: =$H$21*0.8 -> 446292 | L21: =$H$21*0.75 -> 418398.75 | M21: =$H$21*0.7 -> 390505.5 | N21: =$H$21*0.65 -> 362612.25 | O21: =$H$21*0.6 -> 334719 | P21: =$H$21*0.55 -> 306825.75
H22: =(D12+E12+F12)/C12 -> 480783.24 | I22: =$H$22*0.9 -> 432704.92 | J22: =$H$22*0.85 -> 408665.75 | K22: =$H$22*0.8 -> 384626.59 | L22: =$H$22*0.75 -> 360587.43 | M22: =$H$22*0.7 -> 336548.27 | N22: =$H$22*0.65 -> 312509.11 | O22: =$H$22*0.6 -> 288469.94 | P22: =$H$22*0.55 -> 264430.78
