Workbook
Name 라이센스유형: [1]코드표!$G$91:$G$98

Sheet 개발진척현황
A1: ◈ 누적 진척현황 | C1: 2017.03.02
A2: 업무구분 | C2: 총 본수 | D2: 개발 | K2: PL 검수 | R2: IT검수/승인 | Z2: TFT검수/승인 | AH2: 1차 | AI2: 2차
D3: 계획 | E3: 실적 | F3: 지연 | G3: 개발 시작 | H3: 당일 계획 | I3: 달성률 | J3: 완료율 | K3: 계획 | L3: Pass | N3: 지연 | O3: 결함 (L1) | P3: Pass율 (계획대비) | Q3: Pass율 (전체대비) | R3: 총본수 | S3: 계획 | T3: Pass | V3: 지연 | W3: 결함 (L1) | X3: Pass율 (계획대비) | Y3: Pass율 (전체대비) | Z3: 총본수 | AA3: 계획 | AB3: Pass | AD3: 지연 | AE3: 결함 (L1) | AF3: Pass율 (계획대비) | AG3: Pass율 (전체대비)
L4: L3 | M4: L2 | T4: L3 | U4: L2 | AB4: L3 | AC4: L2
A5: 마스터 | B5: 공통 | C5: =COUNTIFS(개발일정표!$A:$A,$A$5,개발일정표!$B:$B,$B5,개발일정표!$H:$H,"<>삭제") -> 20 | D5: =COUNTIFS(개발일정표!$A:$A,$A$5,개발일정표!$B:$B,$B5,개발일정표!$H:$H,"<>삭제",개발일정표!$J:$J,"<="&$C$1) -> 18 | E5: =COUNTIFS(개발일정표!$A:$A,$A$5,개발일정표!$B:$B,$B5,개발일정표!$H:$H,"<>삭제",개발일정표!$L:$L,"<="&$C$1) -> 9 | F5: =D5-E5 -> 9 | G5: =COUNTIFS(개발일정표!$A:$A,$A$5,개발일정표!$B:$B,$B5,개발일정표!$H:$H,"<>삭제",개발일정표!$K:$K,"<="&$C$1,개발일정표!$L:$L,"") -> 8 | H5: =COUNTIFS(개발일정표!$A:$A,$A$5,개발일정표!$B:$B,$B5,개발일정표!$H:$H,"<>삭제",개발일정표!$J:$J,"="&$C$1) -> 2 | I5: =IF(D5=0,0,E5/D5) -> 0.5 | J5: =IF(C5=0,0,E5/C5) -> 0.45 | K5: =COUNTIFS(개발일정표!$A:$A,$A$5,개발일정표!$B:$B,$B5,개발일정표!$H:$H,"<>삭제",개발일정표!$M:$M,"<>검수제외",개발일정표!$O:$O,"<="&$C$1) -> 0 | L5: =COUNTIFS(개발일정표!$A:$A,$A$5,개발일정표!$B:$B,$B5,개발일정표!$H:$H,"<>삭제",개발일정표!$M:$M,"<>검수제외",개발일정표!$R:$R,"=L3",개발일정표!$Q:$Q,"<="&$C$1)+COUNTIFS(개발일정표!$A:$A,$A$5,개발일정표!$B:$B,$B5,개발일정표!$H:$H,"<>삭제",개발일정표!$M:$M,"<>검수제외",개발일정표!$R:$R,"=L1",개발일정표!$S:$S,"=Y",개발일정표!$Q:$Q,"<="&$C$1)+COUNTIFS(개발일정표!$A:$A,$A$5,개발일정표!$B:$B,$B5,개발일정표!$H:$H,"<>삭제",개발일정표!$M:$M,"<>검수제외",개발일정표!$R:$R,"=L2",개발일정표!$S:$S,"=Y",개발일정표!$Q:$Q,"<="&$C$1) -> 0 | M5: =COUNTIFS(개발일정표!$A:$A,$A$5,개발일정표!$B:$B,$B5,개발일정표!$H:$H,"<>삭제",개발일정표!$M:$M,"<>검수제외",개발일정표!$R:$R,"=L2")-COUNTIFS(개발일정표!$A:$A,$A$5,개발일정표!$B:$B,$B5,개발일정표!$H:$H,"<>삭제",개발일정표!$M:$M,"<>검수제외",개발일정표!$R:$R,"=L2",개발일정표!$S:$S,"=Y",개발일정표!$Q:$Q,"<="&$C$1) -> 0 | N5: =K5-(L5+M5) -> 0 | O5: =COUNTIFS(개발일정표!$A:$A,$A$5,개발일정표!$B:$B,$B5,개발일정표!$H:$H,"<>삭제",개발일정표!$M:$M,"<>검수제외",개발일정표!$R:$R,"=L1")-COUNTIFS(개발일정표!$A:$A,$A$5,개발일정표!$B:$B,$B5,개발일정표!$H:$H,"<>삭제",개발일정표!$M:$M,"<>검수제외",개발일정표!$R:$R,"=L1",개발일정표!$S:$S,"=Y",개발일정표!$Q:$Q,"<="&$C$1) -> 0 | P5: =IF(K5=0, 0,(L5+M5)/K5) -> 0 | Q5: =IF(C5=0,0,(L5+M5)/C5) -> 0 | R5: =COUNTIFS(개발일정표!$A:$A,$A$5,개발일정표!$B:$B,$B5,개발일정표!$H:$H,"<>삭제",개발일정표!$T:$T,"<>검수제외") -> 20 | S5: =COUNTIFS(개발일정표!$A:$A,$A$5,개발일정표!$B:$B,$B5,개발일정표!$H:$H,"<>삭제",개발일정표!$T:$T,"<>검수제외",개발일정표!$V:$V,"<="&$C$1) -> 0 | T5: =COUNTIFS(개발일정표!$A:$A,$A$5,개발일정표!$B:$B,$B5,개발일정표!$H:$H,"<>삭제",개발일정표!$T:$T,"<>검수제외",개발일정표!$Y:$Y,"=L3",개발일정표!$X:$X,"<="&$C$1)+COUNTIFS(개발일정표!$A:$A,$A$5,개발일정표!$B:$B,$B5,개발일정표!$H:$H,"<>삭제",개발일정표!$T:$T,"<>검수제외",개발일정표!$Y:$Y,"=L1",개발일정표!$Z:$Z,"=Y",개발일정표!$X:$X,"<="&$C$1)+COUNTIFS(개발일정표!$A:$A,$A$5,개발일정표!$B:$B,$B5,개발일정표!$H:$H,"<>삭제",개발일정표!$T:$T,"<>검수제외",개발일정표!$Y:$Y,"=L2",개발일정표!$Z:$Z,"=Y",개발일정표!$X:$X,"<="&$C$1) -> 0 | U5: =COUNTIFS(개발일정표!$A:$A,$A$5,개발일정표!$B:$B,$B5,개발일정표!$H:$H,"<>삭제",개발일정표!$T:$T,"<>검수제외",개발일정표!$Y:$Y,"=L2")-COUNTIFS(개발일정표!$A:$A,$A$5,개발일정표!$B:$B,$B5,개발일정표!$H:$H,"<>삭제",개발일정표!$T:$T,"<>검수제외",개발일정표!$Y:$Y,"=L2",개발일정표!$Z:$Z,"=Y",개발일정표!$X:$X,"<="&$C$1) -> 0 | V5: =S5-(T5+U5) -> 0 | W5: =COUNTIFS(개발일정표!$A:$A,$A$5,개발일정표!$B:$B,$B5,개발일정표!$H:$H,"<>삭제",개발일정표!$T:$T,"<>검수제외",개발일정표!$Y:$Y,"=L1")-COUNTIFS(개발일정표!$A:$A,$A$5,개발일정표!$B:$B,$B5,개발일정표!$H:$H,"<>삭제",개발일정표!$T:$T,"<>검수제외",개발일정표!$Y:$Y,"=L1",개발일정표!$Z:$Z,"=Y",개발일정표!$X:$X,"<="&$C$1) -> 0 | X5: =IF(S5=0, 0,(T5+U5)/S5) -> 0 | Y5: =IF(R5=0,0,(T5+U5)/R5) -> 0 | Z5: =COUNTIFS(개발일정표!$A:$A,$A$5,개발일정표!$B:$B,$B5,개발일정표!$H:$H,"<>삭제",개발일정표!$AA:$AA,"<>검수제외") -> 20 | AA5: =COUNTIFS(개발일정표!$A:$A,$A$5,개발일정표!$B:$B,$B5,개발일정표!$H:$H,"<>삭제",개발일정표!$AA:$AA,"<>검수제외",개발일정표!$AC:$AC,"<="&$C$1) -> 0 | AB5: =COUNTIFS(개발일정표!$A:$A,$A$5,개발일정표!$B:$B,$B5,개발일정표!$H:$H,"<>삭제",개발일정표!$AA:$AA,"<>검수제외",개발일정표!$AF:$AF,"=L3",개발일정표!$AE:$AE,"<="&$C$1)+COUNTIFS(개발일정표!$A:$A,$A$5,개발일정표!$B:$B,$B5,개발일정표!$H:$H,"<>삭제",개발일정표!$AA:$AA,"<>검수제외",개발일정표!$AF:$AF,"=L1",개발일정표!$AG:$AG,"=Y",개발일정표!$AE:$AE,"<="&$C$1)+COUNTIFS(개발일정표!$A:$A,$A$5,개발일정표!$B:$B,$B5,개발일정표!$H:$H,"<>삭제",개발일정표!$AA:$AA,"<>검수제외",개발일정표!$AF:$AF,"=L2",개발일정표!$AG:$AG,"=Y",개발일정표!$AE:$AE,"<="&$C$1) -> 0 | AC5: =COUNTIFS(개발일정표!$A:$A,$A$5,개발일정표!$B:$B,$B5,개발일정표!$H:$H,"<>삭제",개발일정표!$AA:$AA,"<>검수제외",개발일정표!$AF:$AF,"=L2")-COUNTIFS(개발일정표!$A:$A,$A$5,개발일정표!$B:$B,$B5,개발일정표!$H:$H,"<>삭제",개발일정표!$AA:$AA,"<>검수제외",개발일정표!$AF:$AF,"=L2",개발일정표!$AG:$AG,"=Y",개발일정표!$AE:$AE,"<="&$C$1) -> 0 | AD5: =AA5-(AB5+AC5) -> 0 | AE5: =COUNTIFS(개발일정표!$A:$A,$A$5,개발일정표!$B:$B,$B5,개발일정표!$H:$H,"<>삭제",개발일정표!$AA:$AA,"<>검수제외",개발일정표!$AF:$AF,"=L1")-COUNTIFS(개발일정표!$A:$A,$A$5,개발일정표!$B:$B,$B5,개발일정표!$H:$H,"<>삭제",개발일정표!$AA:$AA,"<>검수제외",개발일정표!$AF:$AF,"=L1",개발일정표!$AG:$AG,"=Y",개발일정표!$AE:$AE,"<="&$C$1) -> 0 | AF5: =IF(AA5=0, 0,(AB5+AC5)/AA5) -> 0 | AG5: =IF(Z5=0,0,(AB5+AC5)/Z5) -> 0 | AH5: =COUNTIFS(개발일정표!$A:$A,$A$5,개발일정표!$B:$B,$B5,개발일정표!$H:$H,"<>삭제",개발일정표!$J:$J,"<>미정") -> 20 | AI5: =COUNTIFS(개발일정표!$A:$A,$A$5,개발일정표!$B:$B,$B5,개발일정표!$H:$H,"<>삭제",개발일정표!$J:$J,"=미정") -> 0
B6: 시스템 | C6: =COUNTIFS(개발일정표!$A:$A,$A$5,개발일정표!$B:$B,$B6,개발일정표!$H:$H,"<>삭제") -> 11 | D6: =COUNTIFS(개발일정표!$A:$A,$A$5,개발일정표!$B:$B,$B6,개발일정표!$H:$H,"<>삭제",개발일정표!$J:$J,"<="&$C$1) -> 0 | E6: =COUNTIFS(개발일정표!$A:$A,$A$5,개발일정표!$B:$B,$B6,개발일정표!$H:$H,"<>삭제",개발일정표!$L:$L,"<="&$C$1) -> 0 | F6: =D6-E6 -> 0 | G6: =COUNTIFS(개발일정표!$A:$A,$A$5,개발일정표!$B:$B,$B6,개발일정표!$H:$H,"<>삭제",개발일정표!$K:$K,"<="&$C$1,개발일정표!$L:$L,"") -> 0 | H6: =COUNTIFS(개발일정표!$A:$A,$A$5,개발일정표!$B:$B,$B6,개발일정표!$H:$H,"<>삭제",개발일정표!$J:$J,"="&$C$1) -> 0 | I6: =IF(D6=0,0,E6/D6) -> 0 | J6: =IF(C6=0,0,E6/C6) -> 0 | K6: =COUNTIFS(개발일정표!$A:$A,$A$5,개발일정표!$B:$B,$B6,개발일정표!$H:$H,"<>삭제",개발일정표!$M:$M,"<>검수제외",개발일정표!$O:$O,"<="&$C$1) -> 0 | L6: =COUNTIFS(개발일정표!$A:$A,$A$5,개발일정표!$B:$B,$B6,개발일정표!$H:$H,"<>삭제",개발일정표!$M:$M,"<>검수제외",개발일정표!$R:$R,"=L3",개발일정표!$Q:$Q,"<="&$C$1)+COUNTIFS(개발일정표!$A:$A,$A$5,개발일정표!$B:$B,$B6,개발일정표!$H:$H,"<>삭제",개발일정표!$M:$M,"<>검수제외",개발일정표!$R:$R,"=L1",개발일정표!$S:$S,"=Y",개발일정표!$Q:$Q,"<="&$C$1)+COUNTIFS(개발일정표!$A:$A,$A$5,개발일정표!$B:$B,$B6,개발일정표!$H:$H,"<>삭제",개발일정표!$M:$M,"<>검수제외",개발일정표!$R:$R,"=L2",개발일정표!$S:$S,"=Y",개발일정표!$Q:$Q,"<="&$C$1) -> 0 | M6: =COUNTIFS(개발일정표!$A:$A,$A$5,개발일정표!$B:$B,$B6,개발일정표!$H:$H,"<>삭제",개발일정표!$M:$M,"<>검수제외",개발일정표!$R:$R,"=L2")-COUNTIFS(개발일정표!$A:$A,$A$5,개발일정표!$B:$B,$B6,개발일정표!$H:$H,"<>삭제",개발일정표!$M:$M,"<>검수제외",개발일정표!$R:$R,"=L2",개발일정표!$S:$S,"=Y",개발일정표!$Q:$Q,"<="&$C$1) -> 0 | N6: =K6-(L6+M6) -> 0 | O6: =COUNTIFS(개발일정표!$A:$A,$A$5,개발일정표!$B:$B,$B6,개발일정표!$H:$H,"<>삭제",개발일정표!$M:$M,"<>검수제외",개발일정표!$R:$R,"=L1")-COUNTIFS(개발일정표!$A:$A,$A$5,개발일정표!$B:$B,$B6,개발일정표!$H:$H,"<>삭제",개발일정표!$M:$M,"<>검수제외",개발일정표!$R:$R,"=L1",개발일정표!$S:$S,"=Y",개발일정표!$Q:$Q,"<="&$C$1) -> 0 | P6: =IF(K6=0, 0,(L6+M6)/K6) -> 0 | Q6: =IF(C6=0,0,(L6+M6)/C6) -> 0 | R6: =COUNTIFS(개발일정표!$A:$A,$A$5,개발일정표!$B:$B,$B6,개발일정표!$H:$H,"<>삭제",개발일정표!$T:$T,"<>검수제외") -> 11 | S6: =COUNTIFS(개발일정표!$A:$A,$A$5,개발일정표!$B:$B,$B6,개발일정표!$H:$H,"<>삭제",개발일정표!$T:$T,"<>검수제외",개발일정표!$V:$V,"<="&$C$1) -> 0 | T6: =COUNTIFS(개발일정표!$A:$A,$A$5,개발일정표!$B:$B,$B6,개발일정표!$H:$H,"<>삭제",개발일정표!$T:$T,"<>검수제외",개발일정표!$Y:$Y,"=L3",개발일정표!$X:$X,"<="&$C$1)+COUNTIFS(개발일정표!$A:$A,$A$5,개발일정표!$B:$B,$B6,개발일정표!$H:$H,"<>삭제",개발일정표!$T:$T,"<>검수제외",개발일정표!$Y:$Y,"=L1",개발일정표!$Z:$Z,"=Y",개발일정표!$X:$X,"<="&$C$1)+COUNTIFS(개발일정표!$A:$A,$A$5,개발일정표!$B:$B,$B6,개발일정표!$H:$H,"<>삭제",개발일정표!$T:$T,"<>검수제외",개발일정표!$Y:$Y,"=L2",개발일정표!$Z:$Z,"=Y",개발일정표!$X:$X,"<="&$C$1) -> 0 | U6: =COUNTIFS(개발일정표!$A:$A,$A$5,개발일정표!$B:$B,$B6,개발일정표!$H:$H,"<>삭제",개발일정표!$T:$T,"<>검수제외",개발일정표!$Y:$Y,"=L2")-COUNTIFS(개발일정표!$A:$A,$A$5,개발일정표!$B:$B,$B6,개발일정표!$H:$H,"<>삭제",개발일정표!$T:$T,"<>검수제외",개발일정표!$Y:$Y,"=L2",개발일정표!$Z:$Z,"=Y",개발일정표!$X:$X,"<="&$C$1) -> 0 | V6: =S6-(T6+U6) -> 0 | W6: =COUNTIFS(개발일정표!$A:$A,$A$5,개발일정표!$B:$B,$B6,개발일정표!$H:$H,"<>삭제",개발일정표!$T:$T,"<>검수제외",개발일정표!$Y:$Y,"=L1")-COUNTIFS(개발일정표!$A:$A,$A$5,개발일정표!$B:$B,$B6,개발일정표!$H:$H,"<>삭제",개발일정표!$T:$T,"<>검수제외",개발일정표!$Y:$Y,"=L1",개발일정표!$Z:$Z,"=Y",개발일정표!$X:$X,"<="&$C$1) -> 0 | X6: =IF(S6=0, 0,(T6+U6)/S6) -> 0 | Y6: =IF(R6=0,0,(T6+U6)/R6) -> 0 | Z6: =COUNTIFS(개발일정표!$A:$A,$A$5,개발일정표!$B:$B,$B6,개발일정표!$H:$H,"<>삭제",개발일정표!$AA:$AA,"<>검수제외") -> 11 | AA6: =COUNTIFS(개발일정표!$A:$A,$A$5,개발일정표!$B:$B,$B6,개발일정표!$H:$H,"<>삭제",개발일정표!$AA:$AA,"<>검수제외",개발일정표!$AC:$AC,"<="&$C$1) -> 0 | AB6: =COUNTIFS(개발일정표!$A:$A,$A$5,개발일정표!$B:$B,$B6,개발일정표!$H:$H,"<>삭제",개발일정표!$AA:$AA,"<>검수제외",개발일정표!$AF:$AF,"=L3",개발일정표!$AE:$AE,"<="&$C$1)+COUNTIFS(개발일정표!$A:$A,$A$5,개발일정표!$B:$B,$B6,개발일정표!$H:$H,"<>삭제",개발일정표!$AA:$AA,"<>검수제외",개발일정표!$AF:$AF,"=L1",개발일정표!$AG:$AG,"=Y",개발일정표!$AE:$AE,"<="&$C$1)+COUNTIFS(개발일정표!$A:$A,$A$5,개발일정표!$B:$B,$B6,개발일정표!$H:$H,"<>삭제",개발일정표!$AA:$AA,"<>검수제외",개발일정표!$AF:$AF,"=L2",개발일정표!$AG:$AG,"=Y",개발일정표!$AE:$AE,"<="&$C$1) -> 0 | AC6: =COUNTIFS(개발일정표!$A:$A,$A$5,개발일정표!$B:$B,$B6,개발일정표!$H:$H,"<>삭제",개발일정표!$AA:$AA,"<>검수제외",개발일정표!$AF:$AF,"=L2")-COUNTIFS(개발일정표!$A:$A,$A$5,개발일정표!$B:$B,$B6,개발일정표!$H:$H,"<>삭제",개발일정표!$AA:$AA,"<>검수제외",개발일정표!$AF:$AF,"=L2",개발일정표!$AG:$AG,"=Y",개발일정표!$AE:$AE,"<="&$C$1) -> 0 | AD6: =AA6-(AB6+AC6) -> 0 | AE6: =COUNTIFS(개발일정표!$A:$A,$A$5,개발일정표!$B:$B,$B6,개발일정표!$H:$H,"<>삭제",개발일정표!$AA:$AA,"<>검수제외",개발일정표!$AF:$AF,"=L1")-COUNTIFS(개발일정표!$A:$A,$A$5,개발일정표!$B:$B,$B6,개발일정표!$H:$H,"<>삭제",개발일정표!$AA:$AA,"<>검수제외",개발일정표!$AF:$AF,"=L1",개발일정표!$AG:$AG,"=Y",개발일정표!$AE:$AE,"<="&$C$1) -> 0 | AF6: =IF(AA6=0, 0,(AB6+AC6)/AA6) -> 0 | AG6: =IF(Z6=0,0,(AB6+AC6)/Z6) -> 0 | AH6: =COUNTIFS(개발일정표!$A:$A,$A$5,개발일정표!$B:$B,$B6,개발일정표!$H:$H,"<>삭제",개발일정표!$J:$J,"<>미정") -> 0 | AI6: =COUNTIFS(개발일정표!$A:$A,$A$5,개발일정표!$B:$B,$B6,개발일정표!$H:$H,"<>삭제",개발일정표!$J:$J,"=미정") -> 11
B7: 소계 | C7: =SUM(C5:C6) -> 31 | D7: =SUM(D5:D6) -> 18 | E7: =SUM(E5:E6) -> 9 | F7: =SUM(F5:F6) -> 9 | G7: =SUM(G5:G6) -> 8 | H7: =SUM(H5:H6) -> 2 | I7: =IF(D7=0,0,E7/D7) -> 0.5 | J7: =IF(C7=0,0,E7/C7) -> 0.29032258 | K7: =SUM(K5:K6) -> 0 | L7: =SUM(L5:L6) -> 0 | M7: =SUM(M5:M6) -> 0 | N7: =SUM(N5:N6) -> 0 | O7: =SUM(O5:O6) -> 0 | P7: =IF(K7=0, 0,(L7+M7)/K7) -> 0 | Q7: =IF(C7=0,0,(L7+M7)/C7) -> 0 | R7: =SUM(R5:R6) -> 31 | S7: =SUM(S5:S6) -> 0 | T7: =SUM(T5:T6) -> 0 | U7: =SUM(U5:U6) -> 0 | V7: =SUM(V5:V6) -> 0 | W7: =SUM(W5:W6) -> 0 | X7: =IF(S7=0, 0,(T7+U7)/S7) -> 0 | Y7: =IF(R7=0,0,(T7+U7)/R7) -> 0 | Z7: =SUM(Z5:Z6) -> 31 | AA7: =SUM(AA5:AA6) -> 0 | AB7: =SUM(AB5:AB6) -> 0 | AC7: =SUM(AC5:AC6) -> 0 | AD7: =SUM(AD5:AD6) -> 0 | AE7: =SUM(AE5:AE6) -> 0 | AF7: =IF(AA7=0,0,(AB7+AC7)/AA7) -> 0 | AG7: =IF(Z7=0,0,(AB7+AC7)/Z7) -> 0 | AH7: =SUM(AH5:AH6) -> 20 | AI7: =SUM(AI5:AI6) -> 11
A8: 입고 | B8: 입하관리 | C8: =COUNTIFS(개발일정표!$A:$A,$A$8,개발일정표!$B:$B,$B8,개발일정표!$H:$H,"<>삭제") -> 6 | D8: =COUNTIFS(개발일정표!$A:$A,$A$8,개발일정표!$B:$B,$B8,개발일정표!$H:$H,"<>삭제",개발일정표!$J:$J,"<="&$C$1) -> 0 | E8: =COUNTIFS(개발일정표!$A:$A,$A$8,개발일정표!$B:$B,$B8,개발일정표!$H:$H,"<>삭제",개발일정표!$L:$L,"<="&$C$1) -> 0 | F8: =D8-E8 -> 0 | G8: =COUNTIFS(개발일정표!$A:$A,$A$8,개발일정표!$B:$B,$B8,개발일정표!$H:$H,"<>삭제",개발일정표!$K:$K,"<="&$C$1,개발일정표!$L:$L,"") -> 0 | H8: =COUNTIFS(개발일정표!$A:$A,$A$8,개발일정표!$B:$B,$B8,개발일정표!$H:$H,"<>삭제",개발일정표!$J:$J,"="&$C$1) -> 0 | I8: =IF(D8=0,0,E8/D8) -> 0 | J8: =IF(C8=0,0,E8/C8) -> 0 | K8: =COUNTIFS(개발일정표!$A:$A,$A$8,개발일정표!$B:$B,$B8,개발일정표!$H:$H,"<>삭제",개발일정표!$M:$M,"<>검수제외",개발일정표!$O:$O,"<="&$C$1) -> 0 | L8: =COUNTIFS(개발일정표!$A:$A,$A$8,개발일정표!$B:$B,$B8,개발일정표!$H:$H,"<>삭제",개발일정표!$M:$M,"<>검수제외",개발일정표!$R:$R,"=L3",개발일정표!$Q:$Q,"<="&$C$1)+COUNTIFS(개발일정표!$A:$A,$A$8,개발일정표!$B:$B,$B8,개발일정표!$H:$H,"<>삭제",개발일정표!$M:$M,"<>검수제외",개발일정표!$R:$R,"=L1",개발일정표!$S:$S,"=Y",개발일정표!$Q:$Q,"<="&$C$1)+COUNTIFS(개발일정표!$A:$A,$A$8,개발일정표!$B:$B,$B8,개발일정표!$H:$H,"<>삭제",개발일정표!$M:$M,"<>검수제외",개발일정표!$R:$R,"=L2",개발일정표!$S:$S,"=Y",개발일정표!$Q:$Q,"<="&$C$1) -> 0 | M8: =COUNTIFS(개발일정표!$A:$A,$A$8,개발일정표!$B:$B,$B8,개발일정표!$H:$H,"<>삭제",개발일정표!$M:$M,"<>검수제외",개발일정표!$R:$R,"=L2")-COUNTIFS(개발일정표!$A:$A,$A$8,개발일정표!$B:$B,$B8,개발일정표!$H:$H,"<>삭제",개발일정표!$M:$M,"<>검수제외",개발일정표!$R:$R,"=L2",개발일정표!$S:$S,"=Y",개발일정표!$Q:$Q,"<="&$C$1) -> 0 | N8: =K8-(L8+M8) -> 0 | O8: =COUNTIFS(개발일정표!$A:$A,$A$8,개발일정표!$B:$B,$B8,개발일정표!$H:$H,"<>삭제",개발일정표!$M:$M,"<>검수제외",개발일정표!$R:$R,"=L1")-COUNTIFS(개발일정표!$A:$A,$A$8,개발일정표!$B:$B,$B8,개발일정표!$H:$H,"<>삭제",개발일정표!$M:$M,"<>검수제외",개발일정표!$R:$R,"=L1",개발일정표!$S:$S,"=Y",개발일정표!$Q:$Q,"<="&$C$1) -> 0 | P8: =IF(K8=0, 0,(L8+M8)/K8) -> 0 | Q8: =IF(C8=0,0,(L8+M8)/C8) -> 0 | R8: =COUNTIFS(개발일정표!$A:$A,$A$8,개발일정표!$B:$B,$B8,개발일정표!$H:$H,"<>삭제",개발일정표!$T:$T,"<>검수제외") -> 6 | S8: =COUNTIFS(개발일정표!$A:$A,$A$8,개발일정표!$B:$B,$B8,개발일정표!$H:$H,"<>삭제",개발일정표!$T:$T,"<>검수제외",개발일정표!$V:$V,"<="&$C$1) -> 0 | T8: =COUNTIFS(개발일정표!$A:$A,$A$8,개발일정표!$B:$B,$B8,개발일정표!$H:$H,"<>삭제",개발일정표!$T:$T,"<>검수제외",개발일정표!$Y:$Y,"=L3",개발일정표!$X:$X,"<="&$C$1)+COUNTIFS(개발일정표!$A:$A,$A$8,개발일정표!$B:$B,$B8,개발일정표!$H:$H,"<>삭제",개발일정표!$T:$T,"<>검수제외",개발일정표!$Y:$Y,"=L1",개발일정표!$Z:$Z,"=Y",개발일정표!$X:$X,"<="&$C$1)+COUNTIFS(개발일정표!$A:$A,$A$8,개발일정표!$B:$B,$B8,개발일정표!$H:$H,"<>삭제",개발일정표!$T:$T,"<>검수제외",개발일정표!$Y:$Y,"=L2",개발일정표!$Z:$Z,"=Y",개발일정표!$X:$X,"<="&$C$1) -> 0 | U8: =COUNTIFS(개발일정표!$A:$A,$A$8,개발일정표!$B:$B,$B8,개발일정표!$H:$H,"<>삭제",개발일정표!$T:$T,"<>검수제외",개발일정표!$Y:$Y,"=L2")-COUNTIFS(개발일정표!$A:$A,$A$8,개발일정표!$B:$B,$B8,개발일정표!$H:$H,"<>삭제",개발일정표!$T:$T,"<>검수제외",개발일정표!$Y:$Y,"=L2",개발일정표!$Z:$Z,"=Y",개발일정표!$X:$X,"<="&$C$1) -> 0 | V8: =S8-(T8+U8) -> 0 | W8: =COUNTIFS(개발일정표!$A:$A,$A$8,개발일정표!$B:$B,$B8,개발일정표!$H:$H,"<>삭제",개발일정표!$T:$T,"<>검수제외",개발일정표!$Y:$Y,"=L1")-COUNTIFS(개발일정표!$A:$A,$A$8,개발일정표!$B:$B,$B8,개발일정표!$H:$H,"<>삭제",개발일정표!$T:$T,"<>검수제외",개발일정표!$Y:$Y,"=L1",개발일정표!$Z:$Z,"=Y",개발일정표!$X:$X,"<="&$C$1) -> 0 | X8: =IF(S8=0, 0,(T8+U8)/S8) -> 0 | Y8: =IF(R8=0,0,(T8+U8)/R8) -> 0 | Z8: =COUNTIFS(개발일정표!$A:$A,$A$8,개발일정표!$B:$B,$B8,개발일정표!$H:$H,"<>삭제",개발일정표!$AA:$AA,"<>검수제외") -> 6 | AA8: =COUNTIFS(개발일정표!$A:$A,$A$8,개발일정표!$B:$B,$B8,개발일정표!$H:$H,"<>삭제",개발일정표!$AA:$AA,"<>검수제외",개발일정표!$AC:$AC,"<="&$C$1) -> 0 | AB8: =COUNTIFS(개발일정표!$A:$A,$A$8,개발일정표!$B:$B,$B8,개발일정표!$H:$H,"<>삭제",개발일정표!$AA:$AA,"<>검수제외",개발일정표!$AF:$AF,"=L3",개발일정표!$AE:$AE,"<="&$C$1)+COUNTIFS(개발일정표!$A:$A,$A$8,개발일정표!$B:$B,$B8,개발일정표!$H:$H,"<>삭제",개발일정표!$AA:$AA,"<>검수제외",개발일정표!$AF:$AF,"=L1",개발일정표!$AG:$AG,"=Y",개발일정표!$AE:$AE,"<="&$C$1)+COUNTIFS(개발일정표!$A:$A,$A$8,개발일정표!$B:$B,$B8,개발일정표!$H:$H,"<>삭제",개발일정표!$AA:$AA,"<>검수제외",개발일정표!$AF:$AF,"=L2",개발일정표!$AG:$AG,"=Y",개발일정표!$AE:$AE,"<="&$C$1) -> 0 | AC8: =COUNTIFS(개발일정표!$A:$A,$A$8,개발일정표!$B:$B,$B8,개발일정표!$H:$H,"<>삭제",개발일정표!$AA:$AA,"<>검수제외",개발일정표!$AF:$AF,"=L2")-COUNTIFS(개발일정표!$A:$A,$A$8,개발일정표!$B:$B,$B8,개발일정표!$H:$H,"<>삭제",개발일정표!$AA:$AA,"<>검수제외",개발일정표!$AF:$AF,"=L2",개발일정표!$AG:$AG,"=Y",개발일정표!$AE:$AE,"<="&$C$1) -> 0 | AD8: =AA8-(AB8+AC8) -> 0 | AE8: =COUNTIFS(개발일정표!$A:$A,$A$8,개발일정표!$B:$B,$B8,개발일정표!$H:$H,"<>삭제",개발일정표!$AA:$AA,"<>검수제외",개발일정표!$AF:$AF,"=L1")-COUNTIFS(개발일정표!$A:$A,$A$8,개발일정표!$B:$B,$B8,개발일정표!$H:$H,"<>삭제",개발일정표!$AA:$AA,"<>검수제외",개발일정표!$AF:$AF,"=L1",개발일정표!$AG:$AG,"=Y",개발일정표!$AE:$AE,"<="&$C$1) -> 0 | AF8: =IF(AA8=0, 0,(AB8+AC8)/AA8) -> 0 | AG8: =IF(Z8=0,0,(AB8+AC8)/Z8) -> 0 | AH8: =COUNTIFS(개발일정표!$A:$A,$A$8,개발일정표!$B:$B,$B8,개발일정표!$H:$H,"<>삭제",개발일정표!$J:$J,"<>미정") -> 4 | AI8: =COUNTIFS(개발일정표!$A:$A,$A$8,개발일정표!$B:$B,$B8,개발일정표!$H:$H,"<>삭제",개발일정표!$J:$J,"=미정") -> 2
B9: 입고관리 | C9: =COUNTIFS(개발일정표!$A:$A,$A$8,개발일정표!$B:$B,$B9,개발일정표!$H:$H,"<>삭제") -> 5 | D9: =COUNTIFS(개발일정표!$A:$A,$A$8,개발일정표!$B:$B,$B9,개발일정표!$H:$H,"<>삭제",개발일정표!$J:$J,"<="&$C$1) -> 0 | E9: =COUNTIFS(개발일정표!$A:$A,$A$8,개발일정표!$B:$B,$B9,개발일정표!$H:$H,"<>삭제",개발일정표!$L:$L,"<="&$C$1) -> 0 | F9: =D9-E9 -> 0 | G9: =COUNTIFS(개발일정표!$A:$A,$A$8,개발일정표!$B:$B,$B9,개발일정표!$H:$H,"<>삭제",개발일정표!$K:$K,"<="&$C$1,개발일정표!$L:$L,"") -> 0 | H9: =COUNTIFS(개발일정표!$A:$A,$A$8,개발일정표!$B:$B,$B9,개발일정표!$H:$H,"<>삭제",개발일정표!$J:$J,"="&$C$1) -> 0 | I9: =IF(D9=0,0,E9/D9) -> 0 | J9: =IF(C9=0,0,E9/C9) -> 0 | K9: =COUNTIFS(개발일정표!$A:$A,$A$8,개발일정표!$B:$B,$B9,개발일정표!$H:$H,"<>삭제",개발일정표!$M:$M,"<>검수제외",개발일정표!$O:$O,"<="&$C$1) -> 0 | L9: =COUNTIFS(개발일정표!$A:$A,$A$8,개발일정표!$B:$B,$B9,개발일정표!$H:$H,"<>삭제",개발일정표!$M:$M,"<>검수제외",개발일정표!$R:$R,"=L3",개발일정표!$Q:$Q,"<="&$C$1)+COUNTIFS(개발일정표!$A:$A,$A$8,개발일정표!$B:$B,$B9,개발일정표!$H:$H,"<>삭제",개발일정표!$M:$M,"<>검수제외",개발일정표!$R:$R,"=L1",개발일정표!$S:$S,"=Y",개발일정표!$Q:$Q,"<="&$C$1)+COUNTIFS(개발일정표!$A:$A,$A$8,개발일정표!$B:$B,$B9,개발일정표!$H:$H,"<>삭제",개발일정표!$M:$M,"<>검수제외",개발일정표!$R:$R,"=L2",개발일정표!$S:$S,"=Y",개발일정표!$Q:$Q,"<="&$C$1) -> 0 | M9: =COUNTIFS(개발일정표!$A:$A,$A$8,개발일정표!$B:$B,$B9,개발일정표!$H:$H,"<>삭제",개발일정표!$M:$M,"<>검수제외",개발일정표!$R:$R,"=L2")-COUNTIFS(개발일정표!$A:$A,$A$8,개발일정표!$B:$B,$B9,개발일정표!$H:$H,"<>삭제",개발일정표!$M:$M,"<>검수제외",개발일정표!$R:$R,"=L2",개발일정표!$S:$S,"=Y",개발일정표!$Q:$Q,"<="&$C$1) -> 0 | N9: =K9-(L9+M9) -> 0 | O9: =COUNTIFS(개발일정표!$A:$A,$A$8,개발일정표!$B:$B,$B9,개발일정표!$H:$H,"<>삭제",개발일정표!$M:$M,"<>검수제외",개발일정표!$R:$R,"=L1")-COUNTIFS(개발일정표!$A:$A,$A$8,개발일정표!$B:$B,$B9,개발일정표!$H:$H,"<>삭제",개발일정표!$M:$M,"<>검수제외",개발일정표!$R:$R,"=L1",개발일정표!$S:$S,"=Y",개발일정표!$Q:$Q,"<="&$C$1) -> 0 | P9: =IF(K9=0, 0,(L9+M9)/K9) -> 0 | Q9: =IF(C9=0,0,(L9+M9)/C9) -> 0 | R9: =COUNTIFS(개발일정표!$A:$A,$A$8,개발일정표!$B:$B,$B9,개발일정표!$H:$H,"<>삭제",개발일정표!$T:$T,"<>검수제외") -> 5 | S9: =COUNTIFS(개발일정표!$A:$A,$A$8,개발일정표!$B:$B,$B9,개발일정표!$H:$H,"<>삭제",개발일정표!$T:$T,"<>검수제외",개발일정표!$V:$V,"<="&$C$1) -> 0 | T9: =COUNTIFS(개발일정표!$A:$A,$A$8,개발일정표!$B:$B,$B9,개발일정표!$H:$H,"<>삭제",개발일정표!$T:$T,"<>검수제외",개발일정표!$Y:$Y,"=L3",개발일정표!$X:$X,"<="&$C$1)+COUNTIFS(개발일정표!$A:$A,$A$8,개발일정표!$B:$B,$B9,개발일정표!$H:$H,"<>삭제",개발일정표!$T:$T,"<>검수제외",개발일정표!$Y:$Y,"=L1",개발일정표!$Z:$Z,"=Y",개발일정표!$X:$X,"<="&$C$1)+COUNTIFS(개발일정표!$A:$A,$A$8,개발일정표!$B:$B,$B9,개발일정표!$H:$H,"<>삭제",개발일정표!$T:$T,"<>검수제외",개발일정표!$Y:$Y,"=L2",개발일정표!$Z:$Z,"=Y",개발일정표!$X:$X,"<="&$C$1) -> 0 | U9: =COUNTIFS(개발일정표!$A:$A,$A$8,개발일정표!$B:$B,$B9,개발일정표!$H:$H,"<>삭제",개발일정표!$T:$T,"<>검수제외",개발일정표!$Y:$Y,"=L2")-COUNTIFS(개발일정표!$A:$A,$A$8,개발일정표!$B:$B,$B9,개발일정표!$H:$H,"<>삭제",개발일정표!$T:$T,"<>검수제외",개발일정표!$Y:$Y,"=L2",개발일정표!$Z:$Z,"=Y",개발일정표!$X:$X,"<="&$C$1) -> 0 | V9: =S9-(T9+U9) -> 0 | W9: =COUNTIFS(개발일정표!$A:$A,$A$8,개발일정표!$B:$B,$B9,개발일정표!$H:$H,"<>삭제",개발일정표!$T:$T,"<>검수제외",개발일정표!$Y:$Y,"=L1")-COUNTIFS(개발일정표!$A:$A,$A$8,개발일정표!$B:$B,$B9,개발일정표!$H:$H,"<>삭제",개발일정표!$T:$T,"<>검수제외",개발일정표!$Y:$Y,"=L1",개발일정표!$Z:$Z,"=Y",개발일정표!$X:$X,"<="&$C$1) -> 0 | X9: =IF(S9=0, 0,(T9+U9)/S9) -> 0 | Y9: =IF(R9=0,0,(T9+U9)/R9) -> 0 | Z9: =COUNTIFS(개발일정표!$A:$A,$A$8,개발일정표!$B:$B,$B9,개발일정표!$H:$H,"<>삭제",개발일정표!$AA:$AA,"<>검수제외") -> 5 | AA9: =COUNTIFS(개발일정표!$A:$A,$A$8,개발일정표!$B:$B,$B9,개발일정표!$H:$H,"<>삭제",개발일정표!$AA:$AA,"<>검수제외",개발일정표!$AC:$AC,"<="&$C$1) -> 0 | AB9: =COUNTIFS(개발일정표!$A:$A,$A$8,개발일정표!$B:$B,$B9,개발일정표!$H:$H,"<>삭제",개발일정표!$AA:$AA,"<>검수제외",개발일정표!$AF:$AF,"=L3",개발일정표!$AE:$AE,"<="&$C$1)+COUNTIFS(개발일정표!$A:$A,$A$8,개발일정표!$B:$B,$B9,개발일정표!$H:$H,"<>삭제",개발일정표!$AA:$AA,"<>검수제외",개발일정표!$AF:$AF,"=L1",개발일정표!$AG:$AG,"=Y",개발일정표!$AE:$AE,"<="&$C$1)+COUNTIFS(개발일정표!$A:$A,$A$8,개발일정표!$B:$B,$B9,개발일정표!$H:$H,"<>삭제",개발일정표!$AA:$AA,"<>검수제외",개발일정표!$AF:$AF,"=L2",개발일정표!$AG:$AG,"=Y",개발일정표!$AE:$AE,"<="&$C$1) -> 0 | AC9: =COUNTIFS(개발일정표!$A:$A,$A$8,개발일정표!$B:$B,$B9,개발일정표!$H:$H,"<>삭제",개발일정표!$AA:$AA,"<>검수제외",개발일정표!$AF:$AF,"=L2")-COUNTIFS(개발일정표!$A:$A,$A$8,개발일정표!$B:$B,$B9,개발일정표!$H:$H,"<>삭제",개발일정표!$AA:$AA,"<>검수제외",개발일정표!$AF:$AF,"=L2",개발일정표!$AG:$AG,"=Y",개발일정표!$AE:$AE,"<="&$C$1) -> 0 | AD9: =AA9-(AB9+AC9) -> 0 | AE9: =COUNTIFS(개발일정표!$A:$A,$A$8,개발일정표!$B:$B,$B9,개발일정표!$H:$H,"<>삭제",개발일정표!$AA:$AA,"<>검수제외",개발일정표!$AF:$AF,"=L1")-COUNTIFS(개발일정표!$A:$A,$A$8,개발일정표!$B:$B,$B9,개발일정표!$H:$H,"<>삭제",개발일정표!$AA:$AA,"<>검수제외",개발일정표!$AF:$AF,"=L1",개발일정표!$AG:$AG,"=Y",개발일정표!$AE:$AE,"<="&$C$1) -> 0 | AF9: =IF(AA9=0, 0,(AB9+AC9)/AA9) -> 0 | AG9: =IF(Z9=0,0,(AB9+AC9)/Z9) -> 0 | AH9: =COUNTIFS(개발일정표!$A:$A,$A$8,개발일정표!$B:$B,$B9,개발일정표!$H:$H,"<>삭제",개발일정표!$J:$J,"<>미정") -> 3 | AI9: =COUNTIFS(개발일정표!$A:$A,$A$8,개발일정표!$B:$B,$B9,개발일정표!$H:$H,"<>삭제",개발일정표!$J:$J,"=미정") -> 2
B10: 입고현황 | C10: =COUNTIFS(개발일정표!$A:$A,$A$8,개발일정표!$B:$B,$B10,개발일정표!$H:$H,"<>삭제") -> 3 | D10: =COUNTIFS(개발일정표!$A:$A,$A$8,개발일정표!$B:$B,$B10,개발일정표!$H:$H,"<>삭제",개발일정표!$J:$J,"<="&$C$1) -> 0 | E10: =COUNTIFS(개발일정표!$A:$A,$A$8,개발일정표!$B:$B,$B10,개발일정표!$H:$H,"<>삭제",개발일정표!$L:$L,"<="&$C$1) -> 0 | F10: =D10-E10 -> 0 | G10: =COUNTIFS(개발일정표!$A:$A,$A$8,개발일정표!$B:$B,$B10,개발일정표!$H:$H,"<>삭제",개발일정표!$K:$K,"<="&$C$1,개발일정표!$L:$L,"") -> 0 | H10: =COUNTIFS(개발일정표!$A:$A,$A$8,개발일정표!$B:$B,$B10,개발일정표!$H:$H,"<>삭제",개발일정표!$J:$J,"="&$C$1) -> 0 | I10: =IF(D10=0,0,E10/D10) -> 0 | J10: =IF(C10=0,0,E10/C10) -> 0 | K10: =COUNTIFS(개발일정표!$A:$A,$A$8,개발일정표!$B:$B,$B10,개발일정표!$H:$H,"<>삭제",개발일정표!$M:$M,"<>검수제외",개발일정표!$O:$O,"<="&$C$1) -> 0 | L10: =COUNTIFS(개발일정표!$A:$A,$A$8,개발일정표!$B:$B,$B10,개발일정표!$H:$H,"<>삭제",개발일정표!$M:$M,"<>검수제외",개발일정표!$R:$R,"=L3",개발일정표!$Q:$Q,"<="&$C$1)+COUNTIFS(개발일정표!$A:$A,$A$8,개발일정표!$B:$B,$B10,개발일정표!$H:$H,"<>삭제",개발일정표!$M:$M,"<>검수제외",개발일정표!$R:$R,"=L1",개발일정표!$S:$S,"=Y",개발일정표!$Q:$Q,"<="&$C$1)+COUNTIFS(개발일정표!$A:$A,$A$8,개발일정표!$B:$B,$B10,개발일정표!$H:$H,"<>삭제",개발일정표!$M:$M,"<>검수제외",개발일정표!$R:$R,"=L2",개발일정표!$S:$S,"=Y",개발일정표!$Q:$Q,"<="&$C$1) -> 0 | M10: =COUNTIFS(개발일정표!$A:$A,$A$8,개발일정표!$B:$B,$B10,개발일정표!$H:$H,"<>삭제",개발일정표!$M:$M,"<>검수제외",개발일정표!$R:$R,"=L2")-COUNTIFS(개발일정표!$A:$A,$A$8,개발일정표!$B:$B,$B10,개발일정표!$H:$H,"<>삭제",개발일정표!$M:$M,"<>검수제외",개발일정표!$R:$R,"=L2",개발일정표!$S:$S,"=Y",개발일정표!$Q:$Q,"<="&$C$1) -> 0 | N10: =K10-(L10+M10) -> 0 | O10: =COUNTIFS(개발일정표!$A:$A,$A$8,개발일정표!$B:$B,$B10,개발일정표!$H:$H,"<>삭제",개발일정표!$M:$M,"<>검수제외",개발일정표!$R:$R,"=L1")-COUNTIFS(개발일정표!$A:$A,$A$8,개발일정표!$B:$B,$B10,개발일정표!$H:$H,"<>삭제",개발일정표!$M:$M,"<>검수제외",개발일정표!$R:$R,"=L1",개발일정표!$S:$S,"=Y",개발일정표!$Q:$Q,"<="&$C$1) -> 0 | P10: =IF(K10=0, 0,(L10+M10)/K10) -> 0 | Q10: =IF(C10=0,0,(L10+M10)/C10) -> 0 | R10: =COUNTIFS(개발일정표!$A:$A,$A$8,개발일정표!$B:$B,$B10,개발일정표!$H:$H,"<>삭제",개발일정표!$T:$T,"<>검수제외") -> 3 | S10: =COUNTIFS(개발일정표!$A:$A,$A$8,개발일정표!$B:$B,$B10,개발일정표!$H:$H,"<>삭제",개발일정표!$T:$T,"<>검수제외",개발일정표!$V:$V,"<="&$C$1) -> 0 | T10: =COUNTIFS(개발일정표!$A:$A,$A$8,개발일정표!$B:$B,$B10,개발일정표!$H:$H,"<>삭제",개발일정표!$T:$T,"<>검수제외",개발일정표!$Y:$Y,"=L3",개발일정표!$X:$X,"<="&$C$1)+COUNTIFS(개발일정표!$A:$A,$A$8,개발일정표!$B:$B,$B10,개발일정표!$H:$H,"<>삭제",개발일정표!$T:$T,"<>검수제외",개발일정표!$Y:$Y,"=L1",개발일정표!$Z:$Z,"=Y",개발일정표!$X:$X,"<="&$C$1)+COUNTIFS(개발일정표!$A:$A,$A$8,개발일정표!$B:$B,$B10,개발일정표!$H:$H,"<>삭제",개발일정표!$T:$T,"<>검수제외",개발일정표!$Y:$Y,"=L2",개발일정표!$Z:$Z,"=Y",개발일정표!$X:$X,"<="&$C$1) -> 0 | U10: =COUNTIFS(개발일정표!$A:$A,$A$8,개발일정표!$B:$B,$B10,개발일정표!$H:$H,"<>삭제",개발일정표!$T:$T,"<>검수제외",개발일정표!$Y:$Y,"=L2")-COUNTIFS(개발일정표!$A:$A,$A$8,개발일정표!$B:$B,$B10,개발일정표!$H:$H,"<>삭제",개발일정표!$T:$T,"<>검수제외",개발일정표!$Y:$Y,"=L2",개발일정표!$Z:$Z,"=Y",개발일정표!$X:$X,"<="&$C$1) -> 0 | V10: =S10-(T10+U10) -> 0 | W10: =COUNTIFS(개발일정표!$A:$A,$A$8,개발일정표!$B:$B,$B10,개발일정표!$H:$H,"<>삭제",개발일정표!$T:$T,"<>검수제외",개발일정표!$Y:$Y,"=L1")-COUNTIFS(개발일정표!$A:$A,$A$8,개발일정표!$B:$B,$B10,개발일정표!$H:$H,"<>삭제",개발일정표!$T:$T,"<>검수제외",개발일정표!$Y:$Y,"=L1",개발일정표!$Z:$Z,"=Y",개발일정표!$X:$X,"<="&$C$1) -> 0 | X10: =IF(S10=0, 0,(T10+U10)/S10) -> 0 | Y10: =IF(R10=0,0,(T10+U10)/R10) -> 0 | Z10: =COUNTIFS(개발일정표!$A:$A,$A$8,개발일정표!$B:$B,$B10,개발일정표!$H:$H,"<>삭제",개발일정표!$AA:$AA,"<>검수제외") -> 3 | AA10: =COUNTIFS(개발일정표!$A:$A,$A$8,개발일정표!$B:$B,$B10,개발일정표!$H:$H,"<>삭제",개발일정표!$AA:$AA,"<>검수제외",개발일정표!$AC:$AC,"<="&$C$1) -> 0 | AB10: =COUNTIFS(개발일정표!$A:$A,$A$8,개발일정표!$B:$B,$B10,개발일정표!$H:$H,"<>삭제",개발일정표!$AA:$AA,"<>검수제외",개발일정표!$AF:$AF,"=L3",개발일정표!$AE:$AE,"<="&$C$1)+COUNTIFS(개발일정표!$A:$A,$A$8,개발일정표!$B:$B,$B10,개발일정표!$H:$H,"<>삭제",개발일정표!$AA:$AA,"<>검수제외",개발일정표!$AF:$AF,"=L1",개발일정표!$AG:$AG,"=Y",개발일정표!$AE:$AE,"<="&$C$1)+COUNTIFS(개발일정표!$A:$A,$A$8,개발일정표!$B:$B,$B10,개발일정표!$H:$H,"<>삭제",개발일정표!$AA:$AA,"<>검수제외",개발일정표!$AF:$AF,"=L2",개발일정표!$AG:$AG,"=Y",개발일정표!$AE:$AE,"<="&$C$1) -> 0 | AC10: =COUNTIFS(개발일정표!$A:$A,$A$8,개발일정표!$B:$B,$B10,개발일정표!$H:$H,"<>삭제",개발일정표!$AA:$AA,"<>검수제외",개발일정표!$AF:$AF,"=L2")-COUNTIFS(개발일정표!$A:$A,$A$8,개발일정표!$B:$B,$B10,개발일정표!$H:$H,"<>삭제",개발일정표!$AA:$AA,"<>검수제외",개발일정표!$AF:$AF,"=L2",개발일정표!$AG:$AG,"=Y",개발일정표!$AE:$AE,"<="&$C$1) -> 0 | AD10: =AA10-(AB10+AC10) -> 0 | AE10: =COUNTIFS(개발일정표!$A:$A,$A$8,개발일정표!$B:$B,$B10,개발일정표!$H:$H,"<>삭제",개발일정표!$AA:$AA,"<>검수제외",개발일정표!$AF:$AF,"=L1")-COUNTIFS(개발일정표!$A:$A,$A$8,개발일정표!$B:$B,$B10,개발일정표!$H:$H,"<>삭제",개발일정표!$AA:$AA,"<>검수제외",개발일정표!$AF:$AF,"=L1",개발일정표!$AG:$AG,"=Y",개발일정표!$AE:$AE,"<="&$C$1) -> 0 | AF10: =IF(AA10=0, 0,(AB10+AC10)/AA10) -> 0 | AG10: =IF(Z10=0,0,(AB10+AC10)/Z10) -> 0 | AH10: =COUNTIFS(개발일정표!$A:$A,$A$8,개발일정표!$B:$B,$B10,개발일정표!$H:$H,"<>삭제",개발일정표!$J:$J,"<>미정") -> 0 | AI10: =COUNTIFS(개발일정표!$A:$A,$A$8,개발일정표!$B:$B,$B10,개발일정표!$H:$H,"<>삭제",개발일정표!$J:$J,"=미정") -> 3
B11: 이고의뢰 | C11: =COUNTIFS(개발일정표!$A:$A,$A$8,개발일정표!$B:$B,$B11,개발일정표!$H:$H,"<>삭제") -> 2 | D11: =COUNTIFS(개발일정표!$A:$A,$A$8,개발일정표!$B:$B,$B11,개발일정표!$H:$H,"<>삭제",개발일정표!$J:$J,"<="&$C$1) -> 0 | E11: =COUNTIFS(개발일정표!$A:$A,$A$8,개발일정표!$B:$B,$B11,개발일정표!$H:$H,"<>삭제",개발일정표!$L:$L,"<="&$C$1) -> 0 | F11: =D11-E11 -> 0 | G11: =COUNTIFS(개발일정표!$A:$A,$A$8,개발일정표!$B:$B,$B11,개발일정표!$H:$H,"<>삭제",개발일정표!$K:$K,"<="&$C$1,개발일정표!$L:$L,"") -> 0 | H11: =COUNTIFS(개발일정표!$A:$A,$A$8,개발일정표!$B:$B,$B11,개발일정표!$H:$H,"<>삭제",개발일정표!$J:$J,"="&$C$1) -> 0 | I11: =IF(D11=0,0,E11/D11) -> 0 | J11: =IF(C11=0,0,E11/C11) -> 0 | K11: =COUNTIFS(개발일정표!$A:$A,$A$8,개발일정표!$B:$B,$B11,개발일정표!$H:$H,"<>삭제",개발일정표!$M:$M,"<>검수제외",개발일정표!$O:$O,"<="&$C$1) -> 0 | L11: =COUNTIFS(개발일정표!$A:$A,$A$8,개발일정표!$B:$B,$B11,개발일정표!$H:$H,"<>삭제",개발일정표!$M:$M,"<>검수제외",개발일정표!$R:$R,"=L3",개발일정표!$Q:$Q,"<="&$C$1)+COUNTIFS(개발일정표!$A:$A,$A$8,개발일정표!$B:$B,$B11,개발일정표!$H:$H,"<>삭제",개발일정표!$M:$M,"<>검수제외",개발일정표!$R:$R,"=L1",개발일정표!$S:$S,"=Y",개발일정표!$Q:$Q,"<="&$C$1)+COUNTIFS(개발일정표!$A:$A,$A$8,개발일정표!$B:$B,$B11,개발일정표!$H:$H,"<>삭제",개발일정표!$M:$M,"<>검수제외",개발일정표!$R:$R,"=L2",개발일정표!$S:$S,"=Y",개발일정표!$Q:$Q,"<="&$C$1) -> 0 | M11: =COUNTIFS(개발일정표!$A:$A,$A$8,개발일정표!$B:$B,$B11,개발일정표!$H:$H,"<>삭제",개발일정표!$M:$M,"<>검수제외",개발일정표!$R:$R,"=L2")-COUNTIFS(개발일정표!$A:$A,$A$8,개발일정표!$B:$B,$B11,개발일정표!$H:$H,"<>삭제",개발일정표!$M:$M,"<>검수제외",개발일정표!$R:$R,"=L2",개발일정표!$S:$S,"=Y",개발일정표!$Q:$Q,"<="&$C$1) -> 0 | N11: =K11-(L11+M11) -> 0 | O11: =COUNTIFS(개발일정표!$A:$A,$A$8,개발일정표!$B:$B,$B11,개발일정표!$H:$H,"<>삭제",개발일정표!$M:$M,"<>검수제외",개발일정표!$R:$R,"=L1")-COUNTIFS(개발일정표!$A:$A,$A$8,개발일정표!$B:$B,$B11,개발일정표!$H:$H,"<>삭제",개발일정표!$M:$M,"<>검수제외",개발일정표!$R:$R,"=L1",개발일정표!$S:$S,"=Y",개발일정표!$Q:$Q,"<="&$C$1) -> 0 | P11: =IF(K11=0, 0,(L11+M11)/K11) -> 0 | Q11: =IF(C11=0,0,(L11+M11)/C11) -> 0 | R11: =COUNTIFS(개발일정표!$A:$A,$A$8,개발일정표!$B:$B,$B11,개발일정표!$H:$H,"<>삭제",개발일정표!$T:$T,"<>검수제외") -> 2 | S11: =COUNTIFS(개발일정표!$A:$A,$A$8,개발일정표!$B:$B,$B11,개발일정표!$H:$H,"<>삭제",개발일정표!$T:$T,"<>검수제외",개발일정표!$V:$V,"<="&$C$1) -> 0 | T11: =COUNTIFS(개발일정표!$A:$A,$A$8,개발일정표!$B:$B,$B11,개발일정표!$H:$H,"<>삭제",개발일정표!$T:$T,"<>검수제외",개발일정표!$Y:$Y,"=L3",개발일정표!$X:$X,"<="&$C$1)+COUNTIFS(개발일정표!$A:$A,$A$8,개발일정표!$B:$B,$B11,개발일정표!$H:$H,"<>삭제",개발일정표!$T:$T,"<>검수제외",개발일정표!$Y:$Y,"=L1",개발일정표!$Z:$Z,"=Y",개발일정표!$X:$X,"<="&$C$1)+COUNTIFS(개발일정표!$A:$A,$A$8,개발일정표!$B:$B,$B11,개발일정표!$H:$H,"<>삭제",개발일정표!$T:$T,"<>검수제외",개발일정표!$Y:$Y,"=L2",개발일정표!$Z:$Z,"=Y",개발일정표!$X:$X,"<="&$C$1) -> 0 | U11: =COUNTIFS(개발일정표!$A:$A,$A$8,개발일정표!$B:$B,$B11,개발일정표!$H:$H,"<>삭제",개발일정표!$T:$T,"<>검수제외",개발일정표!$Y:$Y,"=L2")-COUNTIFS(개발일정표!$A:$A,$A$8,개발일정표!$B:$B,$B11,개발일정표!$H:$H,"<>삭제",개발일정표!$T:$T,"<>검수제외",개발일정표!$Y:$Y,"=L2",개발일정표!$Z:$Z,"=Y",개발일정표!$X:$X,"<="&$C$1) -> 0 | V11: =S11-(T11+U11) -> 0 | W11: =COUNTIFS(개발일정표!$A:$A,$A$8,개발일정표!$B:$B,$B11,개발일정표!$H:$H,"<>삭제",개발일정표!$T:$T,"<>검수제외",개발일정표!$Y:$Y,"=L1")-COUNTIFS(개발일정표!$A:$A,$A$8,개발일정표!$B:$B,$B11,개발일정표!$H:$H,"<>삭제",개발일정표!$T:$T,"<>검수제외",개발일정표!$Y:$Y,"=L1",개발일정표!$Z:$Z,"=Y",개발일정표!$X:$X,"<="&$C$1) -> 0 | X11: =IF(S11=0, 0,(T11+U11)/S11) -> 0 | Y11: =IF(R11=0,0,(T11+U11)/R11) -> 0 | Z11: =COUNTIFS(개발일정표!$A:$A,$A$8,개발일정표!$B:$B,$B11,개발일정표!$H:$H,"<>삭제",개발일정표!$AA:$AA,"<>검수제외") -> 2 | AA11: =COUNTIFS(개발일정표!$A:$A,$A$8,개발일정표!$B:$B,$B11,개발일정표!$H:$H,"<>삭제",개발일정표!$AA:$AA,"<>검수제외",개발일정표!$AC:$AC,"<="&$C$1) -> 0 | AB11: =COUNTIFS(개발일정표!$A:$A,$A$8,개발일정표!$B:$B,$B11,개발일정표!$H:$H,"<>삭제",개발일정표!$AA:$AA,"<>검수제외",개발일정표!$AF:$AF,"=L3",개발일정표!$AE:$AE,"<="&$C$1)+COUNTIFS(개발일정표!$A:$A,$A$8,개발일정표!$B:$B,$B11,개발일정표!$H:$H,"<>삭제",개발일정표!$AA:$AA,"<>검수제외",개발일정표!$AF:$AF,"=L1",개발일정표!$AG:$AG,"=Y",개발일정표!$AE:$AE,"<="&$C$1)+COUNTIFS(개발일정표!$A:$A,$A$8,개발일정표!$B:$B,$B11,개발일정표!$H:$H,"<>삭제",개발일정표!$AA:$AA,"<>검수제외",개발일정표!$AF:$AF,"=L2",개발일정표!$AG:$AG,"=Y",개발일정표!$AE:$AE,"<="&$C$1) -> 0 | AC11: =COUNTIFS(개발일정표!$A:$A,$A$8,개발일정표!$B:$B,$B11,개발일정표!$H:$H,"<>삭제",개발일정표!$AA:$AA,"<>검수제외",개발일정표!$AF:$AF,"=L2")-COUNTIFS(개발일정표!$A:$A,$A$8,개발일정표!$B:$B,$B11,개발일정표!$H:$H,"<>삭제",개발일정표!$AA:$AA,"<>검수제외",개발일정표!$AF:$AF,"=L2",개발일정표!$AG:$AG,"=Y",개발일정표!$AE:$AE,"<="&$C$1) -> 0 | AD11: =AA11-(AB11+AC11) -> 0 | AE11: =COUNTIFS(개발일정표!$A:$A,$A$8,개발일정표!$B:$B,$B11,개발일정표!$H:$H,"<>삭제",개발일정표!$AA:$AA,"<>검수제외",개발일정표!$AF:$AF,"=L1")-COUNTIFS(개발일정표!$A:$A,$A$8,개발일정표!$B:$B,$B11,개발일정표!$H:$H,"<>삭제",개발일정표!$AA:$AA,"<>검수제외",개발일정표!$AF:$AF,"=L1",개발일정표!$AG:$AG,"=Y",개발일정표!$AE:$AE,"<="&$C$1) -> 0 | AF11: =IF(AA11=0, 0,(AB11+AC11)/AA11) -> 0 | AG11: =IF(Z11=0,0,(AB11+AC11)/Z11) -> 0 | AH11: =COUNTIFS(개발일정표!$A:$A,$A$8,개발일정표!$B:$B,$B11,개발일정표!$H:$H,"<>삭제",개발일정표!$J:$J,"<>미정") -> 2 | AI11: =COUNTIFS(개발일정표!$A:$A,$A$8,개발일정표!$B:$B,$B11,개발일정표!$H:$H,"<>삭제",개발일정표!$J:$J,"=미정") -> 0
B12: 소계 | C12: =SUM(C8:C11) -> 16 | D12: =SUM(D8:D11) -> 0 | E12: =SUM(E8:E11) -> 0 | F12: =SUM(F8:F11) -> 0 | G12: =SUM(G8:G11) -> 0 | H12: =SUM(H8:H11) -> 0 | I12: =IF(D12=0,0,E12/D12) -> 0 | J12: =IF(C12=0,0,E12/C12) -> 0 | K12: =SUM(K8:K11) -> 0 | L12: =SUM(L8:L11) -> 0 | M12: =SUM(M8:M11) -> 0 | N12: =SUM(N8:N11) -> 0 | O12: =SUM(O8:O11) -> 0 | P12: =IF(K12=0, 0,(L12+M12)/K12) -> 0 | Q12: =IF(C12=0,0,(L12+M12)/C12) -> 0 | R12: =SUM(R8:R11) -> 16 | S12: =SUM(S8:S11) -> 0 | T12: =SUM(T8:T11) -> 0 | U12: =SUM(U8:U11) -> 0 | V12: =SUM(V8:V11) -> 0 | W12: =SUM(W8:W11) -> 0 | X12: =IF(S12=0, 0,(T12+U12)/S12) -> 0 | Y12: =IF(R12=0,0,(T12+U12)/R12) -> 0 | Z12: =SUM(Z8:Z11) -> 16 | AA12: =SUM(AA8:AA11) -> 0 | AB12: =SUM(AB8:AB11) -> 0 | AC12: =SUM(AC8:AC11) -> 0 | AD12: =SUM(AD8:AD11) -> 0 | AE12: =SUM(AE8:AE11) -> 0 | AF12: =IF(AA12=0,0,(AB12+AC12)/AA12) -> 0 | AG12: =IF(Z12=0,0,(AB12+AC12)/Z12) -> 0 | AH12: =SUM(AH8:AH11) -> 9 | AI12: =SUM(AI8:AI11) -> 7
A13: 출고 | B13: 출고관리 | C13: =COUNTIFS(개발일정표!$A:$A,$A$13,개발일정표!$B:$B,$B13,개발일정표!$H:$H,"<>삭제") -> 14 | D13: =COUNTIFS(개발일정표!$A:$A,$A$13,개발일정표!$B:$B,$B13,개발일정표!$H:$H,"<>삭제",개발일정표!$J:$J,"<="&$C$1) -> 0 | E13: =COUNTIFS(개발일정표!$A:$A,$A$13,개발일정표!$B:$B,$B13,개발일정표!$H:$H,"<>삭제",개발일정표!$L:$L,"<="&$C$1) -> 0 | F13: =D13-E13 -> 0 | G13: =COUNTIFS(개발일정표!$A:$A,$A$13,개발일정표!$B:$B,$B13,개발일정표!$H:$H,"<>삭제",개발일정표!$K:$K,"<="&$C$1,개발일정표!$L:$L,"") -> 0 | H13: =COUNTIFS(개발일정표!$A:$A,$A$13,개발일정표!$B:$B,$B13,개발일정표!$H:$H,"<>삭제",개발일정표!$J:$J,"="&$C$1) -> 0 | I13: =IF(D13=0,0,E13/D13) -> 0 | J13: =IF(C13=0,0,E13/C13) -> 0 | K13: =COUNTIFS(개발일정표!$A:$A,$A$13,개발일정표!$B:$B,$B13,개발일정표!$H:$H,"<>삭제",개발일정표!$M:$M,"<>검수제외",개발일정표!$O:$O,"<="&$C$1) -> 0 | L13: =COUNTIFS(개발일정표!$A:$A,$A$13,개발일정표!$B:$B,$B13,개발일정표!$H:$H,"<>삭제",개발일정표!$M:$M,"<>검수제외",개발일정표!$R:$R,"=L3",개발일정표!$Q:$Q,"<="&$C$1)+COUNTIFS(개발일정표!$A:$A,$A$13,개발일정표!$B:$B,$B13,개발일정표!$H:$H,"<>삭제",개발일정표!$M:$M,"<>검수제외",개발일정표!$R:$R,"=L1",개발일정표!$S:$S,"=Y",개발일정표!$Q:$Q,"<="&$C$1)+COUNTIFS(개발일정표!$A:$A,$A$13,개발일정표!$B:$B,$B13,개발일정표!$H:$H,"<>삭제",개발일정표!$M:$M,"<>검수제외",개발일정표!$R:$R,"=L2",개발일정표!$S:$S,"=Y",개발일정표!$Q:$Q,"<="&$C$1) -> 0 | M13: =COUNTIFS(개발일정표!$A:$A,$A$13,개발일정표!$B:$B,$B13,개발일정표!$H:$H,"<>삭제",개발일정표!$M:$M,"<>검수제외",개발일정표!$R:$R,"=L2")-COUNTIFS(개발일정표!$A:$A,$A$13,개발일정표!$B:$B,$B13,개발일정표!$H:$H,"<>삭제",개발일정표!$M:$M,"<>검수제외",개발일정표!$R:$R,"=L2",개발일정표!$S:$S,"=Y",개발일정표!$Q:$Q,"<="&$C$1) -> 0 | N13: =K13-(L13+M13) -> 0 | O13: =COUNTIFS(개발일정표!$A:$A,$A$13,개발일정표!$B:$B,$B13,개발일정표!$H:$H,"<>삭제",개발일정표!$M:$M,"<>검수제외",개발일정표!$R:$R,"=L1")-COUNTIFS(개발일정표!$A:$A,$A$13,개발일정표!$B:$B,$B13,개발일정표!$H:$H,"<>삭제",개발일정표!$M:$M,"<>검수제외",개발일정표!$R:$R,"=L1",개발일정표!$S:$S,"=Y",개발일정표!$Q:$Q,"<="&$C$1) -> 0 | P13: =IF(K13=0, 0,(L13+M13)/K13) -> 0 | Q13: =IF(C13=0,0,(L13+M13)/C13) -> 0 | R13: =COUNTIFS(개발일정표!$A:$A,$A$13,개발일정표!$B:$B,$B13,개발일정표!$H:$H,"<>삭제",개발일정표!$T:$T,"<>검수제외") -> 14 | S13: =COUNTIFS(개발일정표!$A:$A,$A$13,개발일정표!$B:$B,$B13,개발일정표!$H:$H,"<>삭제",개발일정표!$T:$T,"<>검수제외",개발일정표!$V:$V,"<="&$C$1) -> 0 | T13: =COUNTIFS(개발일정표!$A:$A,$A$13,개발일정표!$B:$B,$B13,개발일정표!$H:$H,"<>삭제",개발일정표!$T:$T,"<>검수제외",개발일정표!$Y:$Y,"=L3",개발일정표!$X:$X,"<="&$C$1)+COUNTIFS(개발일정표!$A:$A,$A$13,개발일정표!$B:$B,$B13,개발일정표!$H:$H,"<>삭제",개발일정표!$T:$T,"<>검수제외",개발일정표!$Y:$Y,"=L1",개발일정표!$Z:$Z,"=Y",개발일정표!$X:$X,"<="&$C$1)+COUNTIFS(개발일정표!$A:$A,$A$13,개발일정표!$B:$B,$B13,개발일정표!$H:$H,"<>삭제",개발일정표!$T:$T,"<>검수제외",개발일정표!$Y:$Y,"=L2",개발일정표!$Z:$Z,"=Y",개발일정표!$X:$X,"<="&$C$1) -> 0 | U13: =COUNTIFS(개발일정표!$A:$A,$A$13,개발일정표!$B:$B,$B13,개발일정표!$H:$H,"<>삭제",개발일정표!$T:$T,"<>검수제외",개발일정표!$Y:$Y,"=L2")-COUNTIFS(개발일정표!$A:$A,$A$13,개발일정표!$B:$B,$B13,개발일정표!$H:$H,"<>삭제",개발일정표!$T:$T,"<>검수제외",개발일정표!$Y:$Y,"=L2",개발일정표!$Z:$Z,"=Y",개발일정표!$X:$X,"<="&$C$1) -> 0 | V13: =S13-(T13+U13) -> 0 | W13: =COUNTIFS(개발일정표!$A:$A,$A$13,개발일정표!$B:$B,$B13,개발일정표!$H:$H,"<>삭제",개발일정표!$T:$T,"<>검수제외",개발일정표!$Y:$Y,"=L1")-COUNTIFS(개발일정표!$A:$A,$A$13,개발일정표!$B:$B,$B13,개발일정표!$H:$H,"<>삭제",개발일정표!$T:$T,"<>검수제외",개발일정표!$Y:$Y,"=L1",개발일정표!$Z:$Z,"=Y",개발일정표!$X:$X,"<="&$C$1) -> 0 | X13: =IF(S13=0, 0,(T13+U13)/S13) -> 0 | Y13: =IF(R13=0,0,(T13+U13)/R13) -> 0 | Z13: =COUNTIFS(개발일정표!$A:$A,$A$13,개발일정표!$B:$B,$B13,개발일정표!$H:$H,"<>삭제",개발일정표!$AA:$AA,"<>검수제외") -> 14 | AA13: =COUNTIFS(개발일정표!$A:$A,$A$13,개발일정표!$B:$B,$B13,개발일정표!$H:$H,"<>삭제",개발일정표!$AA:$AA,"<>검수제외",개발일정표!$AC:$AC,"<="&$C$1) -> 0 | AB13: =COUNTIFS(개발일정표!$A:$A,$A$13,개발일정표!$B:$B,$B13,개발일정표!$H:$H,"<>삭제",개발일정표!$AA:$AA,"<>검수제외",개발일정표!$AF:$AF,"=L3",개발일정표!$AE:$AE,"<="&$C$1)+COUNTIFS(개발일정표!$A:$A,$A$13,개발일정표!$B:$B,$B13,개발일정표!$H:$H,"<>삭제",개발일정표!$AA:$AA,"<>검수제외",개발일정표!$AF:$AF,"=L1",개발일정표!$AG:$AG,"=Y",개발일정표!$AE:$AE,"<="&$C$1)+COUNTIFS(개발일정표!$A:$A,$A$13,개발일정표!$B:$B,$B13,개발일정표!$H:$H,"<>삭제",개발일정표!$AA:$AA,"<>검수제외",개발일정표!$AF:$AF,"=L2",개발일정표!$AG:$AG,"=Y",개발일정표!$AE:$AE,"<="&$C$1) -> 0 | AC13: =COUNTIFS(개발일정표!$A:$A,$A$13,개발일정표!$B:$B,$B13,개발일정표!$H:$H,"<>삭제",개발일정표!$AA:$AA,"<>검수제외",개발일정표!$AF:$AF,"=L2")-COUNTIFS(개발일정표!$A:$A,$A$13,개발일정표!$B:$B,$B13,개발일정표!$H:$H,"<>삭제",개발일정표!$AA:$AA,"<>검수제외",개발일정표!$AF:$AF,"=L2",개발일정표!$AG:$AG,"=Y",개발일정표!$AE:$AE,"<="&$C$1) -> 0 | AD13: =AA13-(AB13+AC13) -> 0 | AE13: =COUNTIFS(개발일정표!$A:$A,$A$13,개발일정표!$B:$B,$B13,개발일정표!$H:$H,"<>삭제",개발일정표!$AA:$AA,"<>검수제외",개발일정표!$AF:$AF,"=L1")-COUNTIFS(개발일정표!$A:$A,$A$13,개발일정표!$B:$B,$B13,개발일정표!$H:$H,"<>삭제",개발일정표!$AA:$AA,"<>검수제외",개발일정표!$AF:$AF,"=L1",개발일정표!$AG:$AG,"=Y",개발일정표!$AE:$AE,"<="&$C$1) -> 0 | AF13: =IF(AA13=0, 0,(AB13+AC13)/AA13) -> 0 | AG13: =IF(Z13=0,0,(AB13+AC13)/Z13) -> 0 | AH13: =COUNTIFS(개발일정표!$A:$A,$A$13,개발일정표!$B:$B,$B13,개발일정표!$H:$H,"<>삭제",개발일정표!$J:$J,"<>미정") -> 9 | AI13: =COUNTIFS(개발일정표!$A:$A,$A$13,개발일정표!$B:$B,$B13,개발일정표!$H:$H,"<>삭제",개발일정표!$J:$J,"=미정") -> 5
B14: 출하관리 | C14: =COUNTIFS(개발일정표!$A:$A,$A$13,개발일정표!$B:$B,$B14,개발일정표!$H:$H,"<>삭제") -> 6 | D14: =COUNTIFS(개발일정표!$A:$A,$A$13,개발일정표!$B:$B,$B14,개발일정표!$H:$H,"<>삭제",개발일정표!$J:$J,"<="&$C$1) -> 0 | E14: =COUNTIFS(개발일정표!$A:$A,$A$13,개발일정표!$B:$B,$B14,개발일정표!$H:$H,"<>삭제",개발일정표!$L:$L,"<="&$C$1) -> 0 | F14: =D14-E14 -> 0 | G14: =COUNTIFS(개발일정표!$A:$A,$A$13,개발일정표!$B:$B,$B14,개발일정표!$H:$H,"<>삭제",개발일정표!$K:$K,"<="&$C$1,개발일정표!$L:$L,"") -> 0 | H14: =COUNTIFS(개발일정표!$A:$A,$A$13,개발일정표!$B:$B,$B14,개발일정표!$H:$H,"<>삭제",개발일정표!$J:$J,"="&$C$1) -> 0 | I14: =IF(D14=0,0,E14/D14) -> 0 | J14: =IF(C14=0,0,E14/C14) -> 0 | K14: =COUNTIFS(개발일정표!$A:$A,$A$13,개발일정표!$B:$B,$B14,개발일정표!$H:$H,"<>삭제",개발일정표!$M:$M,"<>검수제외",개발일정표!$O:$O,"<="&$C$1) -> 0 | L14: =COUNTIFS(개발일정표!$A:$A,$A$13,개발일정표!$B:$B,$B14,개발일정표!$H:$H,"<>삭제",개발일정표!$M:$M,"<>검수제외",개발일정표!$R:$R,"=L3",개발일정표!$Q:$Q,"<="&$C$1)+COUNTIFS(개발일정표!$A:$A,$A$13,개발일정표!$B:$B,$B14,개발일정표!$H:$H,"<>삭제",개발일정표!$M:$M,"<>검수제외",개발일정표!$R:$R,"=L1",개발일정표!$S:$S,"=Y",개발일정표!$Q:$Q,"<="&$C$1)+COUNTIFS(개발일정표!$A:$A,$A$13,개발일정표!$B:$B,$B14,개발일정표!$H:$H,"<>삭제",개발일정표!$M:$M,"<>검수제외",개발일정표!$R:$R,"=L2",개발일정표!$S:$S,"=Y",개발일정표!$Q:$Q,"<="&$C$1) -> 0 | M14: =COUNTIFS(개발일정표!$A:$A,$A$13,개발일정표!$B:$B,$B14,개발일정표!$H:$H,"<>삭제",개발일정표!$M:$M,"<>검수제외",개발일정표!$R:$R,"=L2")-COUNTIFS(개발일정표!$A:$A,$A$13,개발일정표!$B:$B,$B14,개발일정표!$H:$H,"<>삭제",개발일정표!$M:$M,"<>검수제외",개발일정표!$R:$R,"=L2",개발일정표!$S:$S,"=Y",개발일정표!$Q:$Q,"<="&$C$1) -> 0 | N14: =K14-(L14+M14) -> 0 | O14: =COUNTIFS(개발일정표!$A:$A,$A$13,개발일정표!$B:$B,$B14,개발일정표!$H:$H,"<>삭제",개발일정표!$M:$M,"<>검수제외",개발일정표!$R:$R,"=L1")-COUNTIFS(개발일정표!$A:$A,$A$13,개발일정표!$B:$B,$B14,개발일정표!$H:$H,"<>삭제",개발일정표!$M:$M,"<>검수제외",개발일정표!$R:$R,"=L1",개발일정표!$S:$S,"=Y",개발일정표!$Q:$Q,"<="&$C$1) -> 0 | P14: =IF(K14=0, 0,(L14+M14)/K14) -> 0 | Q14: =IF(C14=0,0,(L14+M14)/C14) -> 0 | R14: =COUNTIFS(개발일정표!$A:$A,$A$13,개발일정표!$B:$B,$B14,개발일정표!$H:$H,"<>삭제",개발일정표!$T:$T,"<>검수제외") -> 6 | S14: =COUNTIFS(개발일정표!$A:$A,$A$13,개발일정표!$B:$B,$B14,개발일정표!$H:$H,"<>삭제",개발일정표!$T:$T,"<>검수제외",개발일정표!$V:$V,"<="&$C$1) -> 0 | T14: =COUNTIFS(개발일정표!$A:$A,$A$13,개발일정표!$B:$B,$B14,개발일정표!$H:$H,"<>삭제",개발일정표!$T:$T,"<>검수제외",개발일정표!$Y:$Y,"=L3",개발일정표!$X:$X,"<="&$C$1)+COUNTIFS(개발일정표!$A:$A,$A$13,개발일정표!$B:$B,$B14,개발일정표!$H:$H,"<>삭제",개발일정표!$T:$T,"<>검수제외",개발일정표!$Y:$Y,"=L1",개발일정표!$Z:$Z,"=Y",개발일정표!$X:$X,"<="&$C$1)+COUNTIFS(개발일정표!$A:$A,$A$13,개발일정표!$B:$B,$B14,개발일정표!$H:$H,"<>삭제",개발일정표!$T:$T,"<>검수제외",개발일정표!$Y:$Y,"=L2",개발일정표!$Z:$Z,"=Y",개발일정표!$X:$X,"<="&$C$1) -> 0 | U14: =COUNTIFS(개발일정표!$A:$A,$A$13,개발일정표!$B:$B,$B14,개발일정표!$H:$H,"<>삭제",개발일정표!$T:$T,"<>검수제외",개발일정표!$Y:$Y,"=L2")-COUNTIFS(개발일정표!$A:$A,$A$13,개발일정표!$B:$B,$B14,개발일정표!$H:$H,"<>삭제",개발일정표!$T:$T,"<>검수제외",개발일정표!$Y:$Y,"=L2",개발일정표!$Z:$Z,"=Y",개발일정표!$X:$X,"<="&$C$1) -> 0 | V14: =S14-(T14+U14) -> 0 | W14: =COUNTIFS(개발일정표!$A:$A,$A$13,개발일정표!$B:$B,$B14,개발일정표!$H:$H,"<>삭제",개발일정표!$T:$T,"<>검수제외",개발일정표!$Y:$Y,"=L1")-COUNTIFS(개발일정표!$A:$A,$A$13,개발일정표!$B:$B,$B14,개발일정표!$H:$H,"<>삭제",개발일정표!$T:$T,"<>검수제외",개발일정표!$Y:$Y,"=L1",개발일정표!$Z:$Z,"=Y",개발일정표!$X:$X,"<="&$C$1) -> 0 | X14: =IF(S14=0, 0,(T14+U14)/S14) -> 0 | Y14: =IF(R14=0,0,(T14+U14)/R14) -> 0 | Z14: =COUNTIFS(개발일정표!$A:$A,$A$13,개발일정표!$B:$B,$B14,개발일정표!$H:$H,"<>삭제",개발일정표!$AA:$AA,"<>검수제외") -> 6 | AA14: =COUNTIFS(개발일정표!$A:$A,$A$13,개발일정표!$B:$B,$B14,개발일정표!$H:$H,"<>삭제",개발일정표!$AA:$AA,"<>검수제외",개발일정표!$AC:$AC,"<="&$C$1) -> 0 | AB14: =COUNTIFS(개발일정표!$A:$A,$A$13,개발일정표!$B:$B,$B14,개발일정표!$H:$H,"<>삭제",개발일정표!$AA:$AA,"<>검수제외",개발일정표!$AF:$AF,"=L3",개발일정표!$AE:$AE,"<="&$C$1)+COUNTIFS(개발일정표!$A:$A,$A$13,개발일정표!$B:$B,$B14,개발일정표!$H:$H,"<>삭제",개발일정표!$AA:$AA,"<>검수제외",개발일정표!$AF:$AF,"=L1",개발일정표!$AG:$AG,"=Y",개발일정표!$AE:$AE,"<="&$C$1)+COUNTIFS(개발일정표!$A:$A,$A$13,개발일정표!$B:$B,$B14,개발일정표!$H:$H,"<>삭제",개발일정표!$AA:$AA,"<>검수제외",개발일정표!$AF:$AF,"=L2",개발일정표!$AG:$AG,"=Y",개발일정표!$AE:$AE,"<="&$C$1) -> 0 | AC14: =COUNTIFS(개발일정표!$A:$A,$A$13,개발일정표!$B:$B,$B14,개발일정표!$H:$H,"<>삭제",개발일정표!$AA:$AA,"<>검수제외",개발일정표!$AF:$AF,"=L2")-COUNTIFS(개발일정표!$A:$A,$A$13,개발일정표!$B:$B,$B14,개발일정표!$H:$H,"<>삭제",개발일정표!$AA:$AA,"<>검수제외",개발일정표!$AF:$AF,"=L2",개발일정표!$AG:$AG,"=Y",개발일정표!$AE:$AE,"<="&$C$1) -> 0 | AD14: =AA14-(AB14+AC14) -> 0 | AE14: =COUNTIFS(개발일정표!$A:$A,$A$13,개발일정표!$B:$B,$B14,개발일정표!$H:$H,"<>삭제",개발일정표!$AA:$AA,"<>검수제외",개발일정표!$AF:$AF,"=L1")-COUNTIFS(개발일정표!$A:$A,$A$13,개발일정표!$B:$B,$B14,개발일정표!$H:$H,"<>삭제",개발일정표!$AA:$AA,"<>검수제외",개발일정표!$AF:$AF,"=L1",개발일정표!$AG:$AG,"=Y",개발일정표!$AE:$AE,"<="&$C$1) -> 0 | AF14: =IF(AA14=0, 0,(AB14+AC14)/AA14) -> 0 | AG14: =IF(Z14=0,0,(AB14+AC14)/Z14) -> 0 | AH14: =COUNTIFS(개발일정표!$A:$A,$A$13,개발일정표!$B:$B,$B14,개발일정표!$H:$H,"<>삭제",개발일정표!$J:$J,"<>미정") -> 4 | AI14: =COUNTIFS(개발일정표!$A:$A,$A$13,개발일정표!$B:$B,$B14,개발일정표!$H:$H,"<>삭제",개발일정표!$J:$J,"=미정") -> 2
B15: 출고현황 | C15: =COUNTIFS(개발일정표!$A:$A,$A$13,개발일정표!$B:$B,$B15,개발일정표!$H:$H,"<>삭제") -> 4 | D15: =COUNTIFS(개발일정표!$A:$A,$A$13,개발일정표!$B:$B,$B15,개발일정표!$H:$H,"<>삭제",개발일정표!$J:$J,"<="&$C$1) -> 0 | E15: =COUNTIFS(개발일정표!$A:$A,$A$13,개발일정표!$B:$B,$B15,개발일정표!$H:$H,"<>삭제",개발일정표!$L:$L,"<="&$C$1) -> 0 | F15: =D15-E15 -> 0 | G15: =COUNTIFS(개발일정표!$A:$A,$A$13,개발일정표!$B:$B,$B15,개발일정표!$H:$H,"<>삭제",개발일정표!$K:$K,"<="&$C$1,개발일정표!$L:$L,"") -> 0 | H15: =COUNTIFS(개발일정표!$A:$A,$A$13,개발일정표!$B:$B,$B15,개발일정표!$H:$H,"<>삭제",개발일정표!$J:$J,"="&$C$1) -> 0 | I15: =IF(D15=0,0,E15/D15) -> 0 | J15: =IF(C15=0,0,E15/C15) -> 0 | K15: =COUNTIFS(개발일정표!$A:$A,$A$13,개발일정표!$B:$B,$B15,개발일정표!$H:$H,"<>삭제",개발일정표!$M:$M,"<>검수제외",개발일정표!$O:$O,"<="&$C$1) -> 0 | L15: =COUNTIFS(개발일정표!$A:$A,$A$13,개발일정표!$B:$B,$B15,개발일정표!$H:$H,"<>삭제",개발일정표!$M:$M,"<>검수제외",개발일정표!$R:$R,"=L3",개발일정표!$Q:$Q,"<="&$C$1)+COUNTIFS(개발일정표!$A:$A,$A$13,개발일정표!$B:$B,$B15,개발일정표!$H:$H,"<>삭제",개발일정표!$M:$M,"<>검수제외",개발일정표!$R:$R,"=L1",개발일정표!$S:$S,"=Y",개발일정표!$Q:$Q,"<="&$C$1)+COUNTIFS(개발일정표!$A:$A,$A$13,개발일정표!$B:$B,$B15,개발일정표!$H:$H,"<>삭제",개발일정표!$M:$M,"<>검수제외",개발일정표!$R:$R,"=L2",개발일정표!$S:$S,"=Y",개발일정표!$Q:$Q,"<="&$C$1) -> 0 | M15: =COUNTIFS(개발일정표!$A:$A,$A$13,개발일정표!$B:$B,$B15,개발일정표!$H:$H,"<>삭제",개발일정표!$M:$M,"<>검수제외",개발일정표!$R:$R,"=L2")-COUNTIFS(개발일정표!$A:$A,$A$13,개발일정표!$B:$B,$B15,개발일정표!$H:$H,"<>삭제",개발일정표!$M:$M,"<>검수제외",개발일정표!$R:$R,"=L2",개발일정표!$S:$S,"=Y",개발일정표!$Q:$Q,"<="&$C$1) -> 0 | N15: =K15-(L15+M15) -> 0 | O15: =COUNTIFS(개발일정표!$A:$A,$A$13,개발일정표!$B:$B,$B15,개발일정표!$H:$H,"<>삭제",개발일정표!$M:$M,"<>검수제외",개발일정표!$R:$R,"=L1")-COUNTIFS(개발일정표!$A:$A,$A$13,개발일정표!$B:$B,$B15,개발일정표!$H:$H,"<>삭제",개발일정표!$M:$M,"<>검수제외",개발일정표!$R:$R,"=L1",개발일정표!$S:$S,"=Y",개발일정표!$Q:$Q,"<="&$C$1) -> 0 | P15: =IF(K15=0, 0,(L15+M15)/K15) -> 0 | Q15: =IF(C15=0,0,(L15+M15)/C15) -> 0 | R15: =COUNTIFS(개발일정표!$A:$A,$A$13,개발일정표!$B:$B,$B15,개발일정표!$H:$H,"<>삭제",개발일정표!$T:$T,"<>검수제외") -> 4 | S15: =COUNTIFS(개발일정표!$A:$A,$A$13,개발일정표!$B:$B,$B15,개발일정표!$H:$H,"<>삭제",개발일정표!$T:$T,"<>검수제외",개발일정표!$V:$V,"<="&$C$1) -> 0 | T15: =COUNTIFS(개발일정표!$A:$A,$A$13,개발일정표!$B:$B,$B15,개발일정표!$H:$H,"<>삭제",개발일정표!$T:$T,"<>검수제외",개발일정표!$Y:$Y,"=L3",개발일정표!$X:$X,"<="&$C$1)+COUNTIFS(개발일정표!$A:$A,$A$13,개발일정표!$B:$B,$B15,개발일정표!$H:$H,"<>삭제",개발일정표!$T:$T,"<>검수제외",개발일정표!$Y:$Y,"=L1",개발일정표!$Z:$Z,"=Y",개발일정표!$X:$X,"<="&$C$1)+COUNTIFS(개발일정표!$A:$A,$A$13,개발일정표!$B:$B,$B15,개발일정표!$H:$H,"<>삭제",개발일정표!$T:$T,"<>검수제외",개발일정표!$Y:$Y,"=L2",개발일정표!$Z:$Z,"=Y",개발일정표!$X:$X,"<="&$C$1) -> 0 | U15: =COUNTIFS(개발일정표!$A:$A,$A$13,개발일정표!$B:$B,$B15,개발일정표!$H:$H,"<>삭제",개발일정표!$T:$T,"<>검수제외",개발일정표!$Y:$Y,"=L2")-COUNTIFS(개발일정표!$A:$A,$A$13,개발일정표!$B:$B,$B15,개발일정표!$H:$H,"<>삭제",개발일정표!$T:$T,"<>검수제외",개발일정표!$Y:$Y,"=L2",개발일정표!$Z:$Z,"=Y",개발일정표!$X:$X,"<="&$C$1) -> 0 | V15: =S15-(T15+U15) -> 0 | W15: =COUNTIFS(개발일정표!$A:$A,$A$13,개발일정표!$B:$B,$B15,개발일정표!$H:$H,"<>삭제",개발일정표!$T:$T,"<>검수제외",개발일정표!$Y:$Y,"=L1")-COUNTIFS(개발일정표!$A:$A,$A$13,개발일정표!$B:$B,$B15,개발일정표!$H:$H,"<>삭제",개발일정표!$T:$T,"<>검수제외",개발일정표!$Y:$Y,"=L1",개발일정표!$Z:$Z,"=Y",개발일정표!$X:$X,"<="&$C$1) -> 0 | X15: =IF(S15=0, 0,(T15+U15)/S15) -> 0 | Y15: =IF(R15=0,0,(T15+U15)/R15) -> 0 | Z15: =COUNTIFS(개발일정표!$A:$A,$A$13,개발일정표!$B:$B,$B15,개발일정표!$H:$H,"<>삭제",개발일정표!$AA:$AA,"<>검수제외") -> 4 | AA15: =COUNTIFS(개발일정표!$A:$A,$A$13,개발일정표!$B:$B,$B15,개발일정표!$H:$H,"<>삭제",개발일정표!$AA:$AA,"<>검수제외",개발일정표!$AC:$AC,"<="&$C$1) -> 0 | AB15: =COUNTIFS(개발일정표!$A:$A,$A$13,개발일정표!$B:$B,$B15,개발일정표!$H:$H,"<>삭제",개발일정표!$AA:$AA,"<>검수제외",개발일정표!$AF:$AF,"=L3",개발일정표!$AE:$AE,"<="&$C$1)+COUNTIFS(개발일정표!$A:$A,$A$13,개발일정표!$B:$B,$B15,개발일정표!$H:$H,"<>삭제",개발일정표!$AA:$AA,"<>검수제외",개발일정표!$AF:$AF,"=L1",개발일정표!$AG:$AG,"=Y",개발일정표!$AE:$AE,"<="&$C$1)+COUNTIFS(개발일정표!$A:$A,$A$13,개발일정표!$B:$B,$B15,개발일정표!$H:$H,"<>삭제",개발일정표!$AA:$AA,"<>검수제외",개발일정표!$AF:$AF,"=L2",개발일정표!$AG:$AG,"=Y",개발일정표!$AE:$AE,"<="&$C$1) -> 0 | AC15: =COUNTIFS(개발일정표!$A:$A,$A$13,개발일정표!$B:$B,$B15,개발일정표!$H:$H,"<>삭제",개발일정표!$AA:$AA,"<>검수제외",개발일정표!$AF:$AF,"=L2")-COUNTIFS(개발일정표!$A:$A,$A$13,개발일정표!$B:$B,$B15,개발일정표!$H:$H,"<>삭제",개발일정표!$AA:$AA,"<>검수제외",개발일정표!$AF:$AF,"=L2",개발일정표!$AG:$AG,"=Y",개발일정표!$AE:$AE,"<="&$C$1) -> 0 | AD15: =AA15-(AB15+AC15) -> 0 | AE15: =COUNTIFS(개발일정표!$A:$A,$A$13,개발일정표!$B:$B,$B15,개발일정표!$H:$H,"<>삭제",개발일정표!$AA:$AA,"<>검수제외",개발일정표!$AF:$AF,"=L1")-COUNTIFS(개발일정표!$A:$A,$A$13,개발일정표!$B:$B,$B15,개발일정표!$H:$H,"<>삭제",개발일정표!$AA:$AA,"<>검수제외",개발일정표!$AF:$AF,"=L1",개발일정표!$AG:$AG,"=Y",개발일정표!$AE:$AE,"<="&$C$1) -> 0 | AF15: =IF(AA15=0, 0,(AB15+AC15)/AA15) -> 0 | AG15: =IF(Z15=0,0,(AB15+AC15)/Z15) -> 0 | AH15: =COUNTIFS(개발일정표!$A:$A,$A$13,개발일정표!$B:$B,$B15,개발일정표!$H:$H,"<>삭제",개발일정표!$J:$J,"<>미정") -> 0 | AI15: =COUNTIFS(개발일정표!$A:$A,$A$13,개발일정표!$B:$B,$B15,개발일정표!$H:$H,"<>삭제",개발일정표!$J:$J,"=미정") -> 4
B16: 소계 | C16: =SUM(C13:C15) -> 24 | D16: =SUM(D13:D15) -> 0 | E16: =SUM(E13:E15) -> 0 | F16: =SUM(F13:F15) -> 0 | G16: =SUM(G13:G15) -> 0 | H16: =SUM(H13:H15) -> 0 | I16: =IF(D16=0,0,E16/D16) -> 0 | J16: =IF(C16=0,0,E16/C16) -> 0 | K16: =SUM(K13:K15) -> 0 | L16: =SUM(L13:L15) -> 0 | M16: =SUM(M13:M15) -> 0 | N16: =SUM(N13:N15) -> 0 | O16: =SUM(O13:O15) -> 0 | P16: =IF(K16=0, 0,(L16+M16)/K16) -> 0 | Q16: =IF(C16=0,0,(L16+M16)/C16) -> 0 | R16: =SUM(R13:R15) -> 24 | S16: =SUM(S13:S15) -> 0 | T16: =SUM(T13:T15) -> 0 | U16: =SUM(U13:U15) -> 0 | V16: =SUM(V13:V15) -> 0 | W16: =SUM(W13:W15) -> 0 | X16: =IF(S16=0, 0,(T16+U16)/S16) -> 0 | Y16: =IF(R16=0,0,(T16+U16)/R16) -> 0 | Z16: =SUM(Z13:Z15) -> 24 | AA16: =SUM(AA13:AA15) -> 0 | AB16: =SUM(AB13:AB15) -> 0 | AC16: =SUM(AC13:AC15) -> 0 | AD16: =SUM(AD13:AD15) -> 0 | AE16: =SUM(AE13:AE15) -> 0 | AF16: =IF(AA16=0,0,(AB16+AC16)/AA16) -> 0 | AG16: =IF(Z16=0,0,(AB16+AC16)/Z16) -> 0 | AH16: =SUM(AH13:AH15) -> 13 | AI16: =SUM(AI13:AI15) -> 11
A17: 반입 | B17: 반입관리 | C17: =COUNTIFS(개발일정표!$A:$A,$A$17,개발일정표!$B:$B,$B17,개발일정표!$H:$H,"<>삭제") -> 5 | D17: =COUNTIFS(개발일정표!$A:$A,$A$17,개발일정표!$B:$B,$B17,개발일정표!$H:$H,"<>삭제",개발일정표!$J:$J,"<="&$C$1) -> 0 | E17: =COUNTIFS(개발일정표!$A:$A,$A$17,개발일정표!$B:$B,$B17,개발일정표!$H:$H,"<>삭제",개발일정표!$L:$L,"<="&$C$1) -> 0 | F17: =D17-E17 -> 0 | G17: =COUNTIFS(개발일정표!$A:$A,$A$17,개발일정표!$B:$B,$B17,개발일정표!$H:$H,"<>삭제",개발일정표!$K:$K,"<="&$C$1,개발일정표!$L:$L,"") -> 0 | H17: =COUNTIFS(개발일정표!$A:$A,$A$17,개발일정표!$B:$B,$B17,개발일정표!$H:$H,"<>삭제",개발일정표!$J:$J,"="&$C$1) -> 0 | I17: =IF(D17=0,0,E17/D17) -> 0 | J17: =IF(C17=0,0,E17/C17) -> 0 | K17: =COUNTIFS(개발일정표!$A:$A,$A$17,개발일정표!$B:$B,$B17,개발일정표!$H:$H,"<>삭제",개발일정표!$M:$M,"<>검수제외",개발일정표!$O:$O,"<="&$C$1) -> 0 | L17: =COUNTIFS(개발일정표!$A:$A,$A$17,개발일정표!$B:$B,$B17,개발일정표!$H:$H,"<>삭제",개발일정표!$M:$M,"<>검수제외",개발일정표!$R:$R,"=L3",개발일정표!$Q:$Q,"<="&$C$1)+COUNTIFS(개발일정표!$A:$A,$A$17,개발일정표!$B:$B,$B17,개발일정표!$H:$H,"<>삭제",개발일정표!$M:$M,"<>검수제외",개발일정표!$R:$R,"=L1",개발일정표!$S:$S,"=Y",개발일정표!$Q:$Q,"<="&$C$1)+COUNTIFS(개발일정표!$A:$A,$A$17,개발일정표!$B:$B,$B17,개발일정표!$H:$H,"<>삭제",개발일정표!$M:$M,"<>검수제외",개발일정표!$R:$R,"=L2",개발일정표!$S:$S,"=Y",개발일정표!$Q:$Q,"<="&$C$1) -> 0 | M17: =COUNTIFS(개발일정표!$A:$A,$A$17,개발일정표!$B:$B,$B17,개발일정표!$H:$H,"<>삭제",개발일정표!$M:$M,"<>검수제외",개발일정표!$R:$R,"=L2")-COUNTIFS(개발일정표!$A:$A,$A$17,개발일정표!$B:$B,$B17,개발일정표!$H:$H,"<>삭제",개발일정표!$M:$M,"<>검수제외",개발일정표!$R:$R,"=L2",개발일정표!$S:$S,"=Y",개발일정표!$Q:$Q,"<="&$C$1) -> 0 | N17: =K17-(L17+M17) -> 0 | O17: =COUNTIFS(개발일정표!$A:$A,$A$17,개발일정표!$B:$B,$B17,개발일정표!$H:$H,"<>삭제",개발일정표!$M:$M,"<>검수제외",개발일정표!$R:$R,"=L1")-COUNTIFS(개발일정표!$A:$A,$A$17,개발일정표!$B:$B,$B17,개발일정표!$H:$H,"<>삭제",개발일정표!$M:$M,"<>검수제외",개발일정표!$R:$R,"=L1",개발일정표!$S:$S,"=Y",개발일정표!$Q:$Q,"<="&$C$1) -> 0 | P17: =IF(K17=0, 0,(L17+M17)/K17) -> 0 | Q17: =IF(C17=0,0,(L17+M17)/C17) -> 0 | R17: =COUNTIFS(개발일정표!$A:$A,$A$17,개발일정표!$B:$B,$B17,개발일정표!$H:$H,"<>삭제",개발일정표!$T:$T,"<>검수제외") -> 5 | S17: =COUNTIFS(개발일정표!$A:$A,$A$17,개발일정표!$B:$B,$B17,개발일정표!$H:$H,"<>삭제",개발일정표!$T:$T,"<>검수제외",개발일정표!$V:$V,"<="&$C$1) -> 0 | T17: =COUNTIFS(개발일정표!$A:$A,$A$17,개발일정표!$B:$B,$B17,개발일정표!$H:$H,"<>삭제",개발일정표!$T:$T,"<>검수제외",개발일정표!$Y:$Y,"=L3",개발일정표!$X:$X,"<="&$C$1)+COUNTIFS(개발일정표!$A:$A,$A$17,개발일정표!$B:$B,$B17,개발일정표!$H:$H,"<>삭제",개발일정표!$T:$T,"<>검수제외",개발일정표!$Y:$Y,"=L1",개발일정표!$Z:$Z,"=Y",개발일정표!$X:$X,"<="&$C$1)+COUNTIFS(개발일정표!$A:$A,$A$17,개발일정표!$B:$B,$B17,개발일정표!$H:$H,"<>삭제",개발일정표!$T:$T,"<>검수제외",개발일정표!$Y:$Y,"=L2",개발일정표!$Z:$Z,"=Y",개발일정표!$X:$X,"<="&$C$1) -> 0 | U17: =COUNTIFS(개발일정표!$A:$A,$A$17,개발일정표!$B:$B,$B17,개발일정표!$H:$H,"<>삭제",개발일정표!$T:$T,"<>검수제외",개발일정표!$Y:$Y,"=L2")-COUNTIFS(개발일정표!$A:$A,$A$17,개발일정표!$B:$B,$B17,개발일정표!$H:$H,"<>삭제",개발일정표!$T:$T,"<>검수제외",개발일정표!$Y:$Y,"=L2",개발일정표!$Z:$Z,"=Y",개발일정표!$X:$X,"<="&$C$1) -> 0 | V17: =S17-(T17+U17) -> 0 | W17: =COUNTIFS(개발일정표!$A:$A,$A$17,개발일정표!$B:$B,$B17,개발일정표!$H:$H,"<>삭제",개발일정표!$T:$T,"<>검수제외",개발일정표!$Y:$Y,"=L1")-COUNTIFS(개발일정표!$A:$A,$A$17,개발일정표!$B:$B,$B17,개발일정표!$H:$H,"<>삭제",개발일정표!$T:$T,"<>검수제외",개발일정표!$Y:$Y,"=L1",개발일정표!$Z:$Z,"=Y",개발일정표!$X:$X,"<="&$C$1) -> 0 | X17: =IF(S17=0, 0,(T17+U17)/S17) -> 0 | Y17: =IF(R17=0,0,(T17+U17)/R17) -> 0 | Z17: =COUNTIFS(개발일정표!$A:$A,$A$17,개발일정표!$B:$B,$B17,개발일정표!$H:$H,"<>삭제",개발일정표!$AA:$AA,"<>검수제외") -> 5 | AA17: =COUNTIFS(개발일정표!$A:$A,$A$17,개발일정표!$B:$B,$B17,개발일정표!$H:$H,"<>삭제",개발일정표!$AA:$AA,"<>검수제외",개발일정표!$AC:$AC,"<="&$C$1) -> 0 | AB17: =COUNTIFS(개발일정표!$A:$A,$A$17,개발일정표!$B:$B,$B17,개발일정표!$H:$H,"<>삭제",개발일정표!$AA:$AA,"<>검수제외",개발일정표!$AF:$AF,"=L3",개발일정표!$AE:$AE,"<="&$C$1)+COUNTIFS(개발일정표!$A:$A,$A$17,개발일정표!$B:$B,$B17,개발일정표!$H:$H,"<>삭제",개발일정표!$AA:$AA,"<>검수제외",개발일정표!$AF:$AF,"=L1",개발일정표!$AG:$AG,"=Y",개발일정표!$AE:$AE,"<="&$C$1)+COUNTIFS(개발일정표!$A:$A,$A$17,개발일정표!$B:$B,$B17,개발일정표!$H:$H,"<>삭제",개발일정표!$AA:$AA,"<>검수제외",개발일정표!$AF:$AF,"=L2",개발일정표!$AG:$AG,"=Y",개발일정표!$AE:$AE,"<="&$C$1) -> 0 | AC17: =COUNTIFS(개발일정표!$A:$A,$A$17,개발일정표!$B:$B,$B17,개발일정표!$H:$H,"<>삭제",개발일정표!$AA:$AA,"<>검수제외",개발일정표!$AF:$AF,"=L2")-COUNTIFS(개발일정표!$A:$A,$A$17,개발일정표!$B:$B,$B17,개발일정표!$H:$H,"<>삭제",개발일정표!$AA:$AA,"<>검수제외",개발일정표!$AF:$AF,"=L2",개발일정표!$AG:$AG,"=Y",개발일정표!$AE:$AE,"<="&$C$1) -> 0 | AD17: =AA17-(AB17+AC17) -> 0 | AE17: =COUNTIFS(개발일정표!$A:$A,$A$17,개발일정표!$B:$B,$B17,개발일정표!$H:$H,"<>삭제",개발일정표!$AA:$AA,"<>검수제외",개발일정표!$AF:$AF,"=L1")-COUNTIFS(개발일정표!$A:$A,$A$17,개발일정표!$B:$B,$B17,개발일정표!$H:$H,"<>삭제",개발일정표!$AA:$AA,"<>검수제외",개발일정표!$AF:$AF,"=L1",개발일정표!$AG:$AG,"=Y",개발일정표!$AE:$AE,"<="&$C$1) -> 0 | AF17: =IF(AA17=0, 0,(AB17+AC17)/AA17) -> 0 | AG17: =IF(Z17=0,0,(AB17+AC17)/Z17) -> 0 | AH17: =COUNTIFS(개발일정표!$A:$A,$A$17,개발일정표!$B:$B,$B17,개발일정표!$H:$H,"<>삭제",개발일정표!$J:$J,"<>미정") -> 4 | AI17: =COUNTIFS(개발일정표!$A:$A,$A$17,개발일정표!$B:$B,$B17,개발일정표!$H:$H,"<>삭제",개발일정표!$J:$J,"=미정") -> 1
B18: 소계 | C18: =SUM(C17:C17) -> 5 | D18: =SUM(D17:D17) -> 0 | E18: =SUM(E17:E17) -> 0 | F18: =SUM(F17:F17) -> 0 | G18: =SUM(G17:G17) -> 0 | H18: =SUM(H17:H17) -> 0 | I18: =IF(D18=0,0,E18/D18) -> 0 | J18: =IF(C18=0,0,E18/C18) -> 0 | K18: =SUM(K17:K17) -> 0 | L18: =SUM(L17:L17) -> 0 | M18: =SUM(M17:M17) -> 0 | N18: =SUM(N17:N17) -> 0 | O18: =SUM(O17:O17) -> 0 | P18: =IF(K18=0, 0,(L18+M18)/K18) -> 0 | Q18: =IF(C18=0,0,(L18+M18)/C18) -> 0 | R18: =SUM(R17:R17) -> 5 | S18: =SUM(S17:S17) -> 0 | T18: =SUM(T17:T17) -> 0 | U18: =SUM(U17:U17) -> 0 | V18: =SUM(V17:V17) -> 0 | W18: =SUM(W17:W17) -> 0 | X18: =IF(S18=0, 0,(T18+U18)/S18) -> 0 | Y18: =IF(R18=0,0,(T18+U18)/R18) -> 0 | Z18: =SUM(Z17:Z17) -> 5 | AA18: =SUM(AA17:AA17) -> 0 | AB18: =SUM(AB17:AB17) -> 0 | AC18: =SUM(AC17:AC17) -> 0 | AD18: =SUM(AD17:AD17) -> 0 | AE18: =SUM(AE17:AE17) -> 0 | AF18: =IF(AA18=0,0,(AB18+AC18)/AA18) -> 0 | AG18: =IF(Z18=0,0,(AB18+AC18)/Z18) -> 0 | AH18: =SUM(AH17:AH17) -> 4 | AI18: =SUM(AI17:AI17) -> 1
A19: 반출 | B19: 반출관리 | C19: =COUNTIFS(개발일정표!$A:$A,$A$19,개발일정표!$B:$B,$B19,개발일정표!$H:$H,"<>삭제") -> 5 | D19: =COUNTIFS(개발일정표!$A:$A,$A$19,개발일정표!$B:$B,$B19,개발일정표!$H:$H,"<>삭제",개발일정표!$J:$J,"<="&$C$1) -> 0 | E19: =COUNTIFS(개발일정표!$A:$A,$A$19,개발일정표!$B:$B,$B19,개발일정표!$H:$H,"<>삭제",개발일정표!$L:$L,"<="&$C$1) -> 0 | F19: =D19-E19 -> 0 | G19: =COUNTIFS(개발일정표!$A:$A,$A$19,개발일정표!$B:$B,$B19,개발일정표!$H:$H,"<>삭제",개발일정표!$K:$K,"<="&$C$1,개발일정표!$L:$L,"") -> 0 | H19: =COUNTIFS(개발일정표!$A:$A,$A$19,개발일정표!$B:$B,$B19,개발일정표!$H:$H,"<>삭제",개발일정표!$J:$J,"="&$C$1) -> 0 | I19: =IF(D19=0,0,E19/D19) -> 0 | J19: =IF(C19=0,0,E19/C19) -> 0 | K19: =COUNTIFS(개발일정표!$A:$A,$A$19,개발일정표!$B:$B,$B19,개발일정표!$H:$H,"<>삭제",개발일정표!$M:$M,"<>검수제외",개발일정표!$O:$O,"<="&$C$1) -> 0 | L19: =COUNTIFS(개발일정표!$A:$A,$A$19,개발일정표!$B:$B,$B19,개발일정표!$H:$H,"<>삭제",개발일정표!$M:$M,"<>검수제외",개발일정표!$R:$R,"=L3",개발일정표!$Q:$Q,"<="&$C$1)+COUNTIFS(개발일정표!$A:$A,$A$19,개발일정표!$B:$B,$B19,개발일정표!$H:$H,"<>삭제",개발일정표!$M:$M,"<>검수제외",개발일정표!$R:$R,"=L1",개발일정표!$S:$S,"=Y",개발일정표!$Q:$Q,"<="&$C$1)+COUNTIFS(개발일정표!$A:$A,$A$19,개발일정표!$B:$B,$B19,개발일정표!$H:$H,"<>삭제",개발일정표!$M:$M,"<>검수제외",개발일정표!$R:$R,"=L2",개발일정표!$S:$S,"=Y",개발일정표!$Q:$Q,"<="&$C$1) -> 0 | M19: =COUNTIFS(개발일정표!$A:$A,$A$19,개발일정표!$B:$B,$B19,개발일정표!$H:$H,"<>삭제",개발일정표!$M:$M,"<>검수제외",개발일정표!$R:$R,"=L2")-COUNTIFS(개발일정표!$A:$A,$A$19,개발일정표!$B:$B,$B19,개발일정표!$H:$H,"<>삭제",개발일정표!$M:$M,"<>검수제외",개발일정표!$R:$R,"=L2",개발일정표!$S:$S,"=Y",개발일정표!$Q:$Q,"<="&$C$1) -> 0 | N19: =K19-(L19+M19) -> 0 | O19: =COUNTIFS(개발일정표!$A:$A,$A$19,개발일정표!$B:$B,$B19,개발일정표!$H:$H,"<>삭제",개발일정표!$M:$M,"<>검수제외",개발일정표!$R:$R,"=L1")-COUNTIFS(개발일정표!$A:$A,$A$19,개발일정표!$B:$B,$B19,개발일정표!$H:$H,"<>삭제",개발일정표!$M:$M,"<>검수제외",개발일정표!$R:$R,"=L1",개발일정표!$S:$S,"=Y",개발일정표!$Q:$Q,"<="&$C$1) -> 0 | P19: =IF(K19=0, 0,(L19+M19)/K19) -> 0 | Q19: =IF(C19=0,0,(L19+M19)/C19) -> 0 | R19: =COUNTIFS(개발일정표!$A:$A,$A$19,개발일정표!$B:$B,$B19,개발일정표!$H:$H,"<>삭제",개발일정표!$T:$T,"<>검수제외") -> 5 | S19: =COUNTIFS(개발일정표!$A:$A,$A$19,개발일정표!$B:$B,$B19,개발일정표!$H:$H,"<>삭제",개발일정표!$T:$T,"<>검수제외",개발일정표!$V:$V,"<="&$C$1) -> 0 | T19: =COUNTIFS(개발일정표!$A:$A,$A$19,개발일정표!$B:$B,$B19,개발일정표!$H:$H,"<>삭제",개발일정표!$T:$T,"<>검수제외",개발일정표!$Y:$Y,"=L3",개발일정표!$X:$X,"<="&$C$1)+COUNTIFS(개발일정표!$A:$A,$A$19,개발일정표!$B:$B,$B19,개발일정표!$H:$H,"<>삭제",개발일정표!$T:$T,"<>검수제외",개발일정표!$Y:$Y,"=L1",개발일정표!$Z:$Z,"=Y",개발일정표!$X:$X,"<="&$C$1)+COUNTIFS(개발일정표!$A:$A,$A$19,개발일정표!$B:$B,$B19,개발일정표!$H:$H,"<>삭제",개발일정표!$T:$T,"<>검수제외",개발일정표!$Y:$Y,"=L2",개발일정표!$Z:$Z,"=Y",개발일정표!$X:$X,"<="&$C$1) -> 0 | U19: =COUNTIFS(개발일정표!$A:$A,$A$19,개발일정표!$B:$B,$B19,개발일정표!$H:$H,"<>삭제",개발일정표!$T:$T,"<>검수제외",개발일정표!$Y:$Y,"=L2")-COUNTIFS(개발일정표!$A:$A,$A$19,개발일정표!$B:$B,$B19,개발일정표!$H:$H,"<>삭제",개발일정표!$T:$T,"<>검수제외",개발일정표!$Y:$Y,"=L2",개발일정표!$Z:$Z,"=Y",개발일정표!$X:$X,"<="&$C$1) -> 0 | V19: =S19-(T19+U19) -> 0 | W19: =COUNTIFS(개발일정표!$A:$A,$A$19,개발일정표!$B:$B,$B19,개발일정표!$H:$H,"<>삭제",개발일정표!$T:$T,"<>검수제외",개발일정표!$Y:$Y,"=L1")-COUNTIFS(개발일정표!$A:$A,$A$19,개발일정표!$B:$B,$B19,개발일정표!$H:$H,"<>삭제",개발일정표!$T:$T,"<>검수제외",개발일정표!$Y:$Y,"=L1",개발일정표!$Z:$Z,"=Y",개발일정표!$X:$X,"<="&$C$1) -> 0 | X19: =IF(S19=0, 0,(T19+U19)/S19) -> 0 | Y19: =IF(R19=0,0,(T19+U19)/R19) -> 0 | Z19: =COUNTIFS(개발일정표!$A:$A,$A$19,개발일정표!$B:$B,$B19,개발일정표!$H:$H,"<>삭제",개발일정표!$AA:$AA,"<>검수제외") -> 5 | AA19: =COUNTIFS(개발일정표!$A:$A,$A$19,개발일정표!$B:$B,$B19,개발일정표!$H:$H,"<>삭제",개발일정표!$AA:$AA,"<>검수제외",개발일정표!$AC:$AC,"<="&$C$1) -> 0 | AB19: =COUNTIFS(개발일정표!$A:$A,$A$19,개발일정표!$B:$B,$B19,개발일정표!$H:$H,"<>삭제",개발일정표!$AA:$AA,"<>검수제외",개발일정표!$AF:$AF,"=L3",개발일정표!$AE:$AE,"<="&$C$1)+COUNTIFS(개발일정표!$A:$A,$A$19,개발일정표!$B:$B,$B19,개발일정표!$H:$H,"<>삭제",개발일정표!$AA:$AA,"<>검수제외",개발일정표!$AF:$AF,"=L1",개발일정표!$AG:$AG,"=Y",개발일정표!$AE:$AE,"<="&$C$1)+COUNTIFS(개발일정표!$A:$A,$A$19,개발일정표!$B:$B,$B19,개발일정표!$H:$H,"<>삭제",개발일정표!$AA:$AA,"<>검수제외",개발일정표!$AF:$AF,"=L2",개발일정표!$AG:$AG,"=Y",개발일정표!$AE:$AE,"<="&$C$1) -> 0 | AC19: =COUNTIFS(개발일정표!$A:$A,$A$19,개발일정표!$B:$B,$B19,개발일정표!$H:$H,"<>삭제",개발일정표!$AA:$AA,"<>검수제외",개발일정표!$AF:$AF,"=L2")-COUNTIFS(개발일정표!$A:$A,$A$19,개발일정표!$B:$B,$B19,개발일정표!$H:$H,"<>삭제",개발일정표!$AA:$AA,"<>검수제외",개발일정표!$AF:$AF,"=L2",개발일정표!$AG:$AG,"=Y",개발일정표!$AE:$AE,"<="&$C$1) -> 0 | AD19: =AA19-(AB19+AC19) -> 0 | AE19: =COUNTIFS(개발일정표!$A:$A,$A$19,개발일정표!$B:$B,$B19,개발일정표!$H:$H,"<>삭제",개발일정표!$AA:$AA,"<>검수제외",개발일정표!$AF:$AF,"=L1")-COUNTIFS(개발일정표!$A:$A,$A$19,개발일정표!$B:$B,$B19,개발일정표!$H:$H,"<>삭제",개발일정표!$AA:$AA,"<>검수제외",개발일정표!$AF:$AF,"=L1",개발일정표!$AG:$AG,"=Y",개발일정표!$AE:$AE,"<="&$C$1) -> 0 | AF19: =IF(AA19=0, 0,(AB19+AC19)/AA19) -> 0 | AG19: =IF(Z19=0,0,(AB19+AC19)/Z19) -> 0 | AH19: =COUNTIFS(개발일정표!$A:$A,$A$19,개발일정표!$B:$B,$B19,개발일정표!$H:$H,"<>삭제",개발일정표!$J:$J,"<>미정") -> 4 | AI19: =COUNTIFS(개발일정표!$A:$A,$A$19,개발일정표!$B:$B,$B19,개발일정표!$H:$H,"<>삭제",개발일정표!$J:$J,"=미정") -> 1
B20: 소계 | C20: =SUM(C19:C19) -> 5 | D20: =SUM(D19:D19) -> 0 | E20: =SUM(E19:E19) -> 0 | F20: =SUM(F19:F19) -> 0 | G20: =SUM(G19:G19) -> 0 | H20: =SUM(H19:H19) -> 0 | I20: =IF(D20=0,0,E20/D20) -> 0 | J20: =IF(C20=0,0,E20/C20) -> 0 | K20: =SUM(K19:K19) -> 0 | L20: =SUM(L19:L19) -> 0 | M20: =SUM(M19:M19) -> 0 | N20: =SUM(N19:N19) -> 0 | O20: =SUM(O19:O19) -> 0 | P20: =IF(K20=0, 0,(L20+M20)/K20) -> 0 | Q20: =IF(C20=0,0,(L20+M20)/C20) -> 0 | R20: =SUM(R19:R19) -> 5 | S20: =SUM(S19:S19) -> 0 | T20: =SUM(T19:T19) -> 0 | U20: =SUM(U19:U19) -> 0 | V20: =SUM(V19:V19) -> 0 | W20: =SUM(W19:W19) -> 0 | X20: =IF(S20=0, 0,(T20+U20)/S20) -> 0 | Y20: =IF(R20=0,0,(T20+U20)/R20) -> 0 | Z20: =SUM(Z19:Z19) -> 5 | AA20: =SUM(AA19:AA19) -> 0 | AB20: =SUM(AB19:AB19) -> 0 | AC20: =SUM(AC19:AC19) -> 0 | AD20: =SUM(AD19:AD19) -> 0 | AE20: =SUM(AE19:AE19) -> 0 | AF20: =IF(AA20=0,0,(AB20+AC20)/AA20) -> 0 | AG20: =IF(Z20=0,0,(AB20+AC20)/Z20) -> 0 | AH20: =SUM(AH19:AH19) -> 4 | AI20: =SUM(AI19:AI19) -> 1
A21: 재고 | B21: 재고관리 | C21: =COUNTIFS(개발일정표!$A:$A,$A$21,개발일정표!$B:$B,$B21,개발일정표!$H:$H,"<>삭제") -> 30 | D21: =COUNTIFS(개발일정표!$A:$A,$A$21,개발일정표!$B:$B,$B21,개발일정표!$H:$H,"<>삭제",개발일정표!$J:$J,"<="&$C$1) -> 0 | E21: =COUNTIFS(개발일정표!$A:$A,$A$21,개발일정표!$B:$B,$B21,개발일정표!$H:$H,"<>삭제",개발일정표!$L:$L,"<="&$C$1) -> 0 | F21: =D21-E21 -> 0 | G21: =COUNTIFS(개발일정표!$A:$A,$A$21,개발일정표!$B:$B,$B21,개발일정표!$H:$H,"<>삭제",개발일정표!$K:$K,"<="&$C$1,개발일정표!$L:$L,"") -> 0 | H21: =COUNTIFS(개발일정표!$A:$A,$A$21,개발일정표!$B:$B,$B21,개발일정표!$H:$H,"<>삭제",개발일정표!$J:$J,"="&$C$1) -> 0 | I21: =IF(D21=0,0,E21/D21) -> 0 | J21: =IF(C21=0,0,E21/C21) -> 0 | K21: =COUNTIFS(개발일정표!$A:$A,$A$21,개발일정표!$B:$B,$B21,개발일정표!$H:$H,"<>삭제",개발일정표!$M:$M,"<>검수제외",개발일정표!$O:$O,"<="&$C$1) -> 0 | L21: =COUNTIFS(개발일정표!$A:$A,$A$21,개발일정표!$B:$B,$B21,개발일정표!$H:$H,"<>삭제",개발일정표!$M:$M,"<>검수제외",개발일정표!$R:$R,"=L3",개발일정표!$Q:$Q,"<="&$C$1)+COUNTIFS(개발일정표!$A:$A,$A$21,개발일정표!$B:$B,$B21,개발일정표!$H:$H,"<>삭제",개발일정표!$M:$M,"<>검수제외",개발일정표!$R:$R,"=L1",개발일정표!$S:$S,"=Y",개발일정표!$Q:$Q,"<="&$C$1)+COUNTIFS(개발일정표!$A:$A,$A$21,개발일정표!$B:$B,$B21,개발일정표!$H:$H,"<>삭제",개발일정표!$M:$M,"<>검수제외",개발일정표!$R:$R,"=L2",개발일정표!$S:$S,"=Y",개발일정표!$Q:$Q,"<="&$C$1) -> 0 | M21: =COUNTIFS(개발일정표!$A:$A,$A$21,개발일정표!$B:$B,$B21,개발일정표!$H:$H,"<>삭제",개발일정표!$M:$M,"<>검수제외",개발일정표!$R:$R,"=L2")-COUNTIFS(개발일정표!$A:$A,$A$21,개발일정표!$B:$B,$B21,개발일정표!$H:$H,"<>삭제",개발일정표!$M:$M,"<>검수제외",개발일정표!$R:$R,"=L2",개발일정표!$S:$S,"=Y",개발일정표!$Q:$Q,"<="&$C$1) -> 0 | N21: =K21-(L21+M21) -> 0 | O21: =COUNTIFS(개발일정표!$A:$A,$A$21,개발일정표!$B:$B,$B21,개발일정표!$H:$H,"<>삭제",개발일정표!$M:$M,"<>검수제외",개발일정표!$R:$R,"=L1")-COUNTIFS(개발일정표!$A:$A,$A$21,개발일정표!$B:$B,$B21,개발일정표!$H:$H,"<>삭제",개발일정표!$M:$M,"<>검수제외",개발일정표!$R:$R,"=L1",개발일정표!$S:$S,"=Y",개발일정표!$Q:$Q,"<="&$C$1) -> 0 | P21: =IF(K21=0, 0,(L21+M21)/K21) -> 0 | Q21: =IF(C21=0,0,(L21+M21)/C21) -> 0 | R21: =COUNTIFS(개발일정표!$A:$A,$A$21,개발일정표!$B:$B,$B21,개발일정표!$H:$H,"<>삭제",개발일정표!$T:$T,"<>검수제외") -> 30 | S21: =COUNTIFS(개발일정표!$A:$A,$A$21,개발일정표!$B:$B,$B21,개발일정표!$H:$H,"<>삭제",개발일정표!$T:$T,"<>검수제외",개발일정표!$V:$V,"<="&$C$1) -> 0 | T21: =COUNTIFS(개발일정표!$A:$A,$A$21,개발일정표!$B:$B,$B21,개발일정표!$H:$H,"<>삭제",개발일정표!$T:$T,"<>검수제외",개발일정표!$Y:$Y,"=L3",개발일정표!$X:$X,"<="&$C$1)+COUNTIFS(개발일정표!$A:$A,$A$21,개발일정표!$B:$B,$B21,개발일정표!$H:$H,"<>삭제",개발일정표!$T:$T,"<>검수제외",개발일정표!$Y:$Y,"=L1",개발일정표!$Z:$Z,"=Y",개발일정표!$X:$X,"<="&$C$1)+COUNTIFS(개발일정표!$A:$A,$A$21,개발일정표!$B:$B,$B21,개발일정표!$H:$H,"<>삭제",개발일정표!$T:$T,"<>검수제외",개발일정표!$Y:$Y,"=L2",개발일정표!$Z:$Z,"=Y",개발일정표!$X:$X,"<="&$C$1) -> 0 | U21: =COUNTIFS(개발일정표!$A:$A,$A$21,개발일정표!$B:$B,$B21,개발일정표!$H:$H,"<>삭제",개발일정표!$T:$T,"<>검수제외",개발일정표!$Y:$Y,"=L2")-COUNTIFS(개발일정표!$A:$A,$A$21,개발일정표!$B:$B,$B21,개발일정표!$H:$H,"<>삭제",개발일정표!$T:$T,"<>검수제외",개발일정표!$Y:$Y,"=L2",개발일정표!$Z:$Z,"=Y",개발일정표!$X:$X,"<="&$C$1) -> 0 | V21: =S21-(T21+U21) -> 0 | W21: =COUNTIFS(개발일정표!$A:$A,$A$21,개발일정표!$B:$B,$B21,개발일정표!$H:$H,"<>삭제",개발일정표!$T:$T,"<>검수제외",개발일정표!$Y:$Y,"=L1")-COUNTIFS(개발일정표!$A:$A,$A$21,개발일정표!$B:$B,$B21,개발일정표!$H:$H,"<>삭제",개발일정표!$T:$T,"<>검수제외",개발일정표!$Y:$Y,"=L1",개발일정표!$Z:$Z,"=Y",개발일정표!$X:$X,"<="&$C$1) -> 0 | X21: =IF(S21=0, 0,(T21+U21)/S21) -> 0 | Y21: =IF(R21=0,0,(T21+U21)/R21) -> 0 | Z21: =COUNTIFS(개발일정표!$A:$A,$A$21,개발일정표!$B:$B,$B21,개발일정표!$H:$H,"<>삭제",개발일정표!$AA:$AA,"<>검수제외") -> 30 | AA21: =COUNTIFS(개발일정표!$A:$A,$A$21,개발일정표!$B:$B,$B21,개발일정표!$H:$H,"<>삭제",개발일정표!$AA:$AA,"<>검수제외",개발일정표!$AC:$AC,"<="&$C$1) -> 0 | AB21: =COUNTIFS(개발일정표!$A:$A,$A$21,개발일정표!$B:$B,$B21,개발일정표!$H:$H,"<>삭제",개발일정표!$AA:$AA,"<>검수제외",개발일정표!$AF:$AF,"=L3",개발일정표!$AE:$AE,"<="&$C$1)+COUNTIFS(개발일정표!$A:$A,$A$21,개발일정표!$B:$B,$B21,개발일정표!$H:$H,"<>삭제",개발일정표!$AA:$AA,"<>검수제외",개발일정표!$AF:$AF,"=L1",개발일정표!$AG:$AG,"=Y",개발일정표!$AE:$AE,"<="&$C$1)+COUNTIFS(개발일정표!$A:$A,$A$21,개발일정표!$B:$B,$B21,개발일정표!$H:$H,"<>삭제",개발일정표!$AA:$AA,"<>검수제외",개발일정표!$AF:$AF,"=L2",개발일정표!$AG:$AG,"=Y",개발일정표!$AE:$AE,"<="&$C$1) -> 0 | AC21: =COUNTIFS(개발일정표!$A:$A,$A$21,개발일정표!$B:$B,$B21,개발일정표!$H:$H,"<>삭제",개발일정표!$AA:$AA,"<>검수제외",개발일정표!$AF:$AF,"=L2")-COUNTIFS(개발일정표!$A:$A,$A$21,개발일정표!$B:$B,$B21,개발일정표!$H:$H,"<>삭제",개발일정표!$AA:$AA,"<>검수제외",개발일정표!$AF:$AF,"=L2",개발일정표!$AG:$AG,"=Y",개발일정표!$AE:$AE,"<="&$C$1) -> 0 | AD21: =AA21-(AB21+AC21) -> 0 | AE21: =COUNTIFS(개발일정표!$A:$A,$A$21,개발일정표!$B:$B,$B21,개발일정표!$H:$H,"<>삭제",개발일정표!$AA:$AA,"<>검수제외",개발일정표!$AF:$AF,"=L1")-COUNTIFS(개발일정표!$A:$A,$A$21,개발일정표!$B:$B,$B21,개발일정표!$H:$H,"<>삭제",개발일정표!$AA:$AA,"<>검수제외",개발일정표!$AF:$AF,"=L1",개발일정표!$AG:$AG,"=Y",개발일정표!$AE:$AE,"<="&$C$1) -> 0 | AF21: =IF(AA21=0, 0,(AB21+AC21)/AA21) -> 0 | AG21: =IF(Z21=0,0,(AB21+AC21)/Z21) -> 0 | AH21: =COUNTIFS(개발일정표!$A:$A,$A$21,개발일정표!$B:$B,$B21,개발일정표!$H:$H,"<>삭제",개발일정표!$J:$J,"<>미정") -> 21 | AI21: =COUNTIFS(개발일정표!$A:$A,$A$21,개발일정표!$B:$B,$B21,개발일정표!$H:$H,"<>삭제",개발일정표!$J:$J,"=미정") -> 9
